Workbook

Sheet Read me
A1: Schema review workbook, genre: privacy (plan task 3.4: merge, split and prune clusters to 40-60 types)
A3: Yellow columns are yours. Grey columns are computed (Clusters, Claims, Noise sample) or proposed by Claude.
A4: Clusters sheet, 'Your action' (dropdown): accept = take the proposed action and type as they are;
A5: keep = the cluster is one type (give it in 'Your type'); merge = it joins the type in 'Your type' with
A6: other clusters; split = it holds several types (list them in 'Your type', comma-separated);
A7: prune = not a genre type (say why in 'Notes'). A row left blank blocks the schema.
A8: Types sheet: the proposed types with every field the frozen schema needs. Edit any cell, delete rows,
A9: add rows. Type ids must match what the Clusters sheet points to. Examples are claim texts.
A10: Severity weight: 1.0 by default; 1.5 for privacy types that GDPR Art. 13/14 or CCPA require.
A11: Section hint: where peers usually state it (used by the ghost-paragraph view).
A12: Label source (privacy): OPP-115 values that count as a positive, one per line, written
A13: 'Category :: Attribute = Value' or just 'Category' (lines are alternatives; '&' joins attribute values that
... A22: Provenance: cluster_run=cluster_v1_s0, name_run=name_72b_privacy_s0, naming=openai:openrouter.ai:qwen/qwen-2.5-72b-instruct@deepinfra/fp8, proposals=final_privacy.yaml

Sheet Summary
A1: Check | B1: Value
A2: Clusters | B2: =COUNTA(Clusters!A2:A75)
A3: Clusters still undecided | B3: =SUMPRODUCT((Clusters!A2:A75<>"")*(Clusters!T2:T75=""))
A4: Clusters pruned (your decisions) | B4: =COUNTIF(Clusters!T2:T75,"prune")
A5: Claims in pruned clusters | B5: =SUMIF(Clusters!T2:T75,"prune",Clusters!B2:B75)
A6: Types on the Types sheet | B6: =COUNTA(Types!A2:A500)
A7: Types within 40-60? | B7: =IF(AND(B6>=40,B6<=60),"yes","no")
A8: Types missing a required field | B8: =SUMPRODUCT((Types!A2:A500<>"")*(((Types!C2:C500="")+(Types!D2:D500="")+(Types!E2:E500="")+(Types!F2:F500="")+(Types!H2:H500="")+(Types!I2:I500=""))>0))
A9: Seeds still undecided | B9: =COUNTBLANK(Seeds!E2:E11)
A10: Kept-or-merged clusters with no type given | B10: =SUMPRODUCT((Clusters!T2:T75<>"")*(Clusters!T2:T75<>"accept")*(Clusters!T2:T75<>"prune")*(Clusters!U2:U75=""))

Sheet Clusters
A1: Cluster | B1: Size | C1: Documents | D1: Document share | E1: Cohesion | F1: Position (0 first, 1 last) | G1: Top headings | H1: Teacher name | I1: Teacher definition | J1: Flags | K1: Split note | L1: Representative 1 | M1: Representative 2 | N1: Representative 3 | O1: Top extraction labels | P1: Nearest clusters (cosine) | Q1: Proposed action | R1: Proposed type | S1: Reason | T1: Your action | U1: Your type | V1: Notes | W1: Effective type
A2: c000 | B2: 956 | C2: 355 | D2: 0.71 | E2: 0.6586 | F2: 0.437 | G2: cookies (236); (no heading) (130); use of cookies (65) | H2: cookie_usage_purposes | I2: States that the company uses cookies for various purposes, including to identify and track users, store preferences, and enhance the user experience. | L2: The company uses cookies to identify which pages on their website have been accessed. | M2: The company uses cookies for various purposes, including to access user information and track preferences. | N2: The company uses cookies to identify and track visitors and their preferences. | O2: cookie_usage (146), disclosing_practice (91), cookie_use (71), data_collection (36), data_use (30) | P2: c050 0.69, c053 0.61, c042 0.58 | Q2: merge | R2: uses_cookies | T2: accept | V2: reviewed on the page; see decisions/page_answers_2026-10-15.json and resolutions_2026-10-15.yaml | W2: =IF(T2="accept",R2,U2)
A3: c001 | B3: 835 | C3: 329 | D3: 0.658 | E3: 0.5602 | F3: 0.326 | G3: (no heading) (142); log files (22); privacy policy (14) | H3: collects_website_usage_data | I3: States that the company collects various types of data about user interactions with the website, including visits, page views, and technical information, but not specific personal data. | L3: The company collects information about the number of users visiting the website and the number of pages viewed. | M3: The company collects information about the visitor's use of the platform such as URLs visited, time spent, and actions taken. | N3: The company collects automated information about how users use and navigate the website. | O3: data_collection (167), data_use (70), specific_data_type (28), data_collection_purpose (23), data_usage (16) | P3: c060 0.73, c052 0.63, c002 0.55 | Q3: merge | R3: collects_usage_data_automatically | T3: accept | V3: reviewed on the page; see decisions/page_answers_2026-10-15.json and resolutions_2026-10-15.yaml | W3: =IF(T3="accept",R3,U3)
A4: c002 | B4: 651 | C4: 333 | D4: 0.666 | E4: 0.687 | F4: 0.178 | G4: (no heading) (107); what information do we collect (31); privacy policy (17) | H4: data_collection_methods | I4: States that the company collects personal information from users through various activities on the website, such as registration, placing orders, or providing information. | L4: The company collects personal information when users register or place an order on the site. | M4: The company collects various types of personal information from users, including contact details and demographic information. | N4: The company collects information when users place orders or enter information on the site. | O4: data_collection (318), data_collection_method (13), specific_data_collection (11), data_collection_purpose (9), data_collection_types (8) | P4: c001 0.55, c021 0.53, c060 0.46 | Q4: keep | R4: data_collection_methods | T4: accept | V4: reviewed on the page; see decisions/page_answers_2026-10-15.json and resolutions_2026-10-15.yaml | W4: =IF(T4="accept",R4,U4)
A5: c003 | B5: 621 | C5: 283 | D5: 0.566 | E5: 0.5407 | F5: 0.468 | G5: (no heading) (108); information sharing (17); do we disclose any information to outside parties (14) | H5: legal_disclosure_conditions | I5: States that the company may disclose personal information when required by law or to protect rights, property, or safety. | L5: The company discloses personal information when required by law or in good-faith belief that such action is necessary to protect rights or comply with legal processes. | M5: The company may disclose personal information as required by legal process or law. | N5: The company reserves the right to disclose personal information when required by law or to protect its rights. | O5: legal_disclosure (116), legal_compliance (20), legal_sharing (11), legal_release (10), disclosure_reason (9) | P5: c031 0.39, c033 0.34, c072 0.33 | Q5: keep | R5: discloses_when_legally_required | T5: accept | V5: reviewed on the page; see decisions/page_answers_2026-10-15.json and resolutions_2026-10-15.yaml | W5: =IF(T5="accept",R5,U5)
A6: c004 | B6: 586 | C6: 341 | D6: 0.682 | E6: 0.6257 | F6: 0.368 | G6: (no heading) (115); privacy policy (20); california online privacy protection act compliance (12) | H6: no_third_party_sharing | I6: States that the company does not share, sell, rent, or otherwise disclose personal information to third parties without permission or legal requirement. | L6: The company does not sell, rent, or trade personal information to third parties. | M6: The company does not share personal information with non-affiliated third parties without permission. | N6: The company will not share personal information with third parties without permission or legal requirement. | O6: data_sharing_policy (78), data_protection (15), no_third_party_sales (14), data_sharing (14), no_third_party_sharing (13) | P6: c027 0.59, c070 0.54, c043 0.51 | Q6: merge | R6: does_not_sell_or_share | T6: accept | V6: reviewed on the page; see decisions/page_answers_2026-10-15.json and resolutions_2026-10-15.yaml | W6: =IF(T6="accept",R6,U6)
A7: c005 | B7: 528 | C7: 240 | D7: 0.48 | E7: 0.6788 | F7: 0.531 | G7: (no heading) (94); choice opt out (33); your california privacy rights (11) | H7: opt_out_communications | I7: States that the company provides users with the option to opt-out of receiving various types of communications, including emails, direct mailings, and phone calls, from the company and its partners. | L7: The company allows users to opt-out of receiving communications from the company. | M7: The company provides users the opportunity to opt-out of receiving communications from the company and its partners. | N7: The company allows users to opt out of receiving email newsletters by selecting specific links or following opt-out instructions. | O7: opt_out_option (28), user_opt_out (26), opt_out_provision (22), opt_out (17), communication_opt_out (13) | P7: c046 0.81, c035 0.80, c054 0.62 | Q7: merge | R7: opt_out_of_communications | T7: accept | V7: reviewed on the page; see decisions/page_answers_2026-10-15.json and resolutions_2026-10-15.yaml | W7: =IF(T7="accept",R7,U7)
A8: c006 | B8: 463 | C8: 258 | D8: 0.516 | E8: 0.5344 | F8: 0.365 | G8: (no heading) (65); what do we use your information for (18); how we use your information (10) | H8: sends_promotional_emails | I8: States that the company may send promotional emails to users about products, services, and special offers, including newsletters and updates. | L8: The company may send promotional emails about new products or special offers. | M8: The company may send promotional emails to users using the provided email address. | N8: The company may send promotional emails about its products, services, and special offers. | O8: data_use (52), disclosing_practice (23), data_collection (17), email_use (13), marketing_communication (13) | P8: c032 0.67, c045 0.40, c049 0.38 | Q8: merge | R8: sends_marketing_communications | T8: accept | V8: reviewed on the page; see decisions/page_answers_2026-10-15.json and resolutions_2026-10-15.yaml | W8: =IF(T8="accept",R8,U8)
A9: c007 | B9: 444 | C9: 303 | D9: 0.606 | E9: 0.7835 | F9: 0.519 | G9: security (87); (no heading) (69); how do we protect your information (14) | H9: states_security_measures | I9: States that the company has implemented or adopted security measures to protect personal information against unauthorized actions, access, disclosure, alteration, or destruction. | L9: The company has implemented security measures to protect personal information. | M9: The company employs appropriate security measures to protect personal information against unauthorized access, disclosure, alteration, or destruction. | N9: The company uses various security technologies and procedures to protect personal information. | O9: security_measures (149), security_commitment (30), security_procedures (15), data_protection (14), data_protection_commitment (11) | P9: c020 0.78, c065 0.72, c017 0.61 | Q9: keep | R9: states_security_measures | T9: accept | V9: reviewed on the page; see decisions/page_answers_2026-10-15.json and resolutions_2026-10-15.yaml | W9: =IF(T9="accept",R9,U9)
A10: c008 | B10: 440 | C10: 252 | D10: 0.504 | E10: 0.5784 | F10: 0.286 | G10: (no heading) (65); how we use your information (11); personal information (10) | H10: data_use_for_services | I10: States that the company uses collected personal information for providing products, services, processing orders, and customer support. | L10: The company uses collected personal information to provide products and services, process orders, and offer customer service. | M10: The company uses collected information to fulfill orders, provide quotes, process orders, notify about order status, prepare drawings, and provide information about offers or products. | N10: The company uses collected information to deliver requested products and services, manage accounts, and provide customer support. | O10: data_use (81), data_collection_purpose (23), service_provision (22), data_collection (17), data_use_purpose (16) | P10: c028 0.61, c057 0.55, c047 0.45 | Q10: keep | R10: data_use_for_services | T10: accept | V10: reviewed on the page; see decisions/page_answers_2026-10-15.json and resolutions_2026-10-15.yaml | W10: =IF(T10="accept",R10,U10)
A11: c009 | B11: 432 | C11: 263 | D11: 0.526 | E11: 0.672 | F11: 0.605 | G11: (no heading) (65); external links (18); links (18) | H11: disclaim_third_party_responsibility | I11: States that the company is not responsible for the content, practices, policies, or privacy of third-party websites linked from its site. | L11: The company is not responsible for the content, policies, practices, or products of third-party websites. | M11: The company is not responsible for the content, privacy, or security practices of third-party websites. | N11: The company is not responsible for the content or privacy practices of third-party websites linked to its website. | O11: third_party_disclaimer (54), disclaim_responsibility (46), third_party_responsibility (17), liability_disclaimer (15), external_site_disclaimer (12) | P11: c023 0.73, c036 0.60, c064 0.55 | Q11: merge | R11: third_party_sites_and_their_policies | T11: accept | V11: reviewed on the page; see decisions/page_answers_2026-10-15.json and resolutions_2026-10-15.yaml | W11: =IF(T11="accept",R11,U11)
A12: c010 | B12: 430 | C12: 264 | D12: 0.528 | E12: 0.6339 | F12: 0.594 | G12: (no heading) (74); changes to this privacy policy (18); links (16) | H12: advice_on_policy_review | I12: Advises users to review, read, or check the privacy policies of other websites, linked sites, or third-party services, and to stay informed about updates or changes. | L12: The company advises users to review the privacy policies of websites they link to. | M12: The company encourages users to review the privacy policy frequently. | N12: The company advises users to regularly check the privacy policy for changes. | O12: user_advice (22), review_encouragement (15), user_information_link (14), third_party_policy_reference (11), advice_to_users (10) | P12: c018 0.59, c064 0.36, c056 0.34 | Q12: merge | R12: third_party_sites_and_their_policies | T12: accept | V12: reviewed on the page; see decisions/page_answers_2026-10-15.json and resolutions_2026-10-15.yaml | W12: =IF(T12="accept",R12,U12)
A13: c011 | B13: 412 | C13: 266 | D13: 0.532 | E13: 0.5104 | F13: 0.11 | G13: (no heading) (184); privacy policy (30); introduction (8) | H13: policy_coverage | I13: States that the privacy policy covers the collection, use, and handling of personal information, typically specifying the scope of the policy to include the company's websites, services, and sometimes its family of companies. | L13: The company discloses that the privacy policy covers the collection, use, and choices about personal information collected on or through the services. | M13: The company explains the scope of its privacy policy to cover personal information provided through its websites. | N13: The company explains that the privacy policy document describes the personal information collected and its usage. | O13: policy_scope (51), policy_purpose (30), policy_coverage (28), policy_description (23), policy_application (15) | P13: c069 0.47, c063 0.39, c029 0.35 | Q13: keep | R13: policy_coverage | T13: accept | V13: reviewed on the page; see decisions/page_answers_2026-10-15.json and resolutions_2026-10-15.yaml | W13: =IF(T13="accept",R13,U13)
... A16: c014 | B16: 308 | C16: 240 | D16: 0.48 | E16: 0.7074 | F16: 0.645 | G16: (no heading) (67); privacy policy (9); contacting us (9) | H16: provides_contact_method | I16: States that the company provides a contact method for questions, concerns, or suggestions about the privacy policy, data security, or related matters. | L16: The company provides a contact method for questions about the privacy policy or services. | M16: The company provides a contact method for questions about the privacy policy. | N16: The company provides an email address for inquiries or requests about the privacy policy or personal information handling. | O16: contact_method (101), contact_information (97), feedback_welcome (9), contact_provision (8), contact_invitation (6) | P16: c048 0.87, c071 0.67, c032 0.47 | Q16: merge | R16: provides_privacy_contact | T16: accept | V16: reviewed on the page; see decisions/page_answers_2026-10-15.json and resolutions_2026-10-15.yaml | W16: =IF(T16="accept",R16,U16)
A17: c015 | B17: 299 | C17: 249 | D17: 0.498 | E17: 0.8294 | F17: 0.65 | G17: (no heading) (63); changes to this privacy policy (35); changes to our privacy policy (8) | H17: policy_change_right | I17: States that the company reserves the right to change, modify, or update the privacy policy at any time, with or without notice. | J17: example_label_name | L17: The company reserves the right to change the privacy policy at any time. | M17: The company reserves the right to modify the privacy policy at any time. | N17: The company reserves the right to change the privacy policy without notice. | O17: policy_change (39), policy_modification_right (38), policy_change_right (36), policy_modification (31), policy_update (29) | P17: c061 0.79, c056 0.71, c073 0.66 | Q17: keep | R17: reserves_right_to_change_policy | T17: accept | V17: reviewed on the page; see decisions/page_answers_2026-10-15.json and resolutions_2026-10-15.yaml | W17: =IF(T17="accept",R17,U17)
A18: c016 | B18: 286 | C18: 175 | D18: 0.35 | E18: 0.7136 | F18: 0.633 | G18: security (60); (no heading) (57); data security (7) | H18: disclaims_internet_security | I18: States that the company cannot guarantee the security of information transmitted over the internet or wireless networks, often emphasizing the inherent risks and limitations of online transmission. | L18: The company cannot guarantee the security of any information transmitted over the internet. | M18: The company cannot guarantee the security of any information transmitted over the Internet or wireless networks. | N18: The company acknowledges that it cannot guarantee 100% security of information transmitted over the Internet. | O18: security_disclaimer (69), security_limitation (43), security_guarantee (11), transmission_risk (10), security_disclosure (6) | P18: c018 0.49, c007 0.47, c020 0.44 | Q18: keep | R18: security_not_guaranteed | T18: accept | V18: reviewed on the page; see decisions/page_answers_2026-10-15.json and resolutions_2026-10-15.yaml | W18: =IF(T18="accept",R18,U18)
A19: c017 | B19: 283 | C19: 235 | D19: 0.47 | E19: 0.7312 | F19: 0.088 | G19: (no heading) (130); privacy policy (24); privacy statement (7) | H19: privacy_commitment | I19: States that the company is committed to protecting and respecting the privacy and personal information of its users. | L19: The company commits to protecting the privacy and personal information of its users. | M19: The company is committed to protecting and respecting the privacy of individuals. | N19: The company is committed to protecting the privacy of its users. | O19: privacy_commitment (153), commitment_to_privacy (11), protection_commitment (8), privacy_acknowledgment (5), privacy_respect (5) | P19: c007 0.61, c038 0.55, c072 0.55 | Q19: keep | R19: states_policy_scope_and_commitment | T19: accept | V19: reviewed on the page; see decisions/page_answers_2026-10-15.json and resolutions_2026-10-15.yaml | W19: =IF(T19="accept",R19,U19)
A20: c018 | B20: 282 | C20: 152 | D20: 0.304 | E20: 0.6224 | F20: 0.584 | G20: (no heading) (45); security (30); public forums (17) | H20: advises_user_security | I20: Advises users to take specific security measures, such as being cautious with personal information, protecting passwords, and securing accounts, but does not include detailed technical requirements or user responsibilities beyond basic security practices. | L20: The company advises users to be cautious when sharing personal information in public areas of the site. | M20: The company advises users to exercise caution with personal information posted on its websites. | N20: The company advises users to protect their passwords and limit access to their accounts. | O20: security_advice (23), user_responsibility (23), user_advice (19), caution_advice (13), public_disclosure_warning (9) | P20: c010 0.59, c016 0.49, c037 0.40 | Q20: keep | R20: advises_users_on_security | T20: accept | V20: reviewed on the page; see decisions/page_answers_2026-10-15.json and resolutions_2026-10-15.yaml | W20: =IF(T20="accept",R20,U20)
A21: c019 | B21: 282 | C21: 171 | D21: 0.342 | E21: 0.7069 | F21: 0.62 | G21: (no heading) (34); children (29); children s privacy (22) | H21: age_restriction_declaration | I21: States that the company restricts the use of its services or websites to individuals above a certain age, typically 13, and may require parental consent for minors. | L21: The company prohibits the use of its websites or services by anyone under 13 years of age. | M21: The company prohibits anyone under the age of 13 from using the service. | N21: The company states that individuals under 13 should not use the site. | O21: age_restriction (31), target_audience_declaration (11), age_requirement (9), intended_audience (7), data_collection_limit (6) | P21: c041 0.79, c068 0.59, c037 0.44 | Q21: keep | R21: states_minimum_age | T21: accept | V21: reviewed on the page; see decisions/page_answers_2026-10-15.json and resolutions_2026-10-15.yaml | W21: =IF(T21="accept",R21,U21)
A22: c020 | B22: 274 | C22: 164 | D22: 0.328 | E22: 0.7256 | F22: 0.523 | G22: (no heading) (43); security (40); how do we protect your information (20) | H22: uses_ssl_encryption | I22: States that the company uses SSL (Secure Sockets Layer) encryption to secure the transmission of sensitive information, including personally identifiable and credit card information, to prevent unauthorized access. | L22: The company uses SSL to encrypt information transmitted over the Internet. | M22: The company uses Secure Sockets Layer (SSL) encryption for sensitive information to prevent unauthorized access. | N22: The company transmits sensitive information via SSL technology and encrypts it. | O22: encryption_method (35), encryption_use (26), encryption_practice (11), data_encryption (11), encryption_technology (9) | P22: c007 0.78, c065 0.67, c072 0.51 | Q22: keep | R22: encrypts_data_in_transit | T22: accept | V22: reviewed on the page; see decisions/page_answers_2026-10-15.json and resolutions_2026-10-15.yaml | W22: =IF(T22="accept",R22,U22)
A23: c021 | B23: 274 | C23: 175 | D23: 0.35 | E23: 0.5321 | F23: 0.325 | G23: (no heading) (40); information collection and use (9); what information do we collect (7) | H23: registration_information_requirements | I23: States that the company requires users to provide specific personal information during the registration process, including details such as name, email address, and unique identifiers. | L23: The company asks for specific personal information when users register. | M23: The company requires users to provide personal information during registration. | N23: The company requires users to provide a username, password, and email address during registration. | O23: registration_requirement (25), identity_verification (24), data_collection (14), data_request (12), required_information (9) | P23: c002 0.53, c032 0.40, c071 0.32 | Q23: keep | R23: states_information_required_to_register | T23: accept | V23: reviewed on the page; see decisions/page_answers_2026-10-15.json and resolutions_2026-10-15.yaml | W23: =IF(T23="accept",R23,U23)
A24: c022 | B24: 273 | C24: 192 | D24: 0.384 | E24: 0.7148 | F24: 0.502 | G24: (no heading) (48); cookies (44); use of cookies (19) | H24: user_cookie_control | I24: States that users can control cookies through their browser settings, including accepting, declining, disabling, or being notified about cookies. | L24: The company allows users to disable cookies through their web browser settings. | M24: The company allows users to decline cookies by adjusting their browser settings. | N24: The company allows users to accept or decline cookies by modifying their browser settings. | O24: user_control (68), granting_right (16), cookie_control (10), user_cookie_control (10), cookie_use (9) | P24: c034 0.74, c035 0.69, c059 0.49 | Q24: keep | R24: browser_cookie_controls | T24: accept | V24: reviewed on the page; see decisions/page_answers_2026-10-15.json and resolutions_2026-10-15.yaml | W24: =IF(T24="accept",R24,U24)
A25: c023 | B25: 263 | C25: 179 | D25: 0.358 | E25: 0.6302 | F25: 0.59 | G25: (no heading) (34); cookies (18); doubleclick dart cookie (7) | H25: disclaims_control_over_third_party_cookies | I25: States that the company does not have access to, control over, or responsibility for cookies used by third-party advertisers or other third-party services. | L25: The company has no access to or control over cookies used by third-party advertisers. | M25: The company does not have access to or control over the cookies used by third-party advertisers. | N25: The company has no access to or control over cookies used by third-party advertisers. | O25: no_control_over_cookies (18), third_party_control (15), third_party_disclaimer (12), third_party_cookies (7), non_control_third_party (6) | P25: c009 0.73, c039 0.55, c036 0.54 | Q25: keep | R25: disclaims_control_of_third_party_cookies | T25: accept | V25: reviewed on the page; see decisions/page_answers_2026-10-15.json and resolutions_2026-10-15.yaml | W25: =IF(T25="accept",R25,U25)
A26: c024 | B26: 251 | C26: 157 | D26: 0.314 | E26: 0.65 | F26: 0.408 | G26: (no heading) (48); information sharing and disclosure (9); personal information (5) | H26: shares_personal_information_with_third_parties | I26: States that the company shares personal information with third parties for the purpose of performing services, fulfilling orders, or other specific functions on behalf of the company. | L26: The company may share personal information with third parties hired to perform services, under strict conditions. | M26: The company shares personal information with third parties providing services on their behalf. | N26: The company may share personal information with third parties to perform services on behalf of the user. | O26: third_party_sharing (27), data_sharing (20), third_party_disclosure (8), disclosure_to_third_parties (7), third_party_access (7) | P26: c030 0.78, c055 0.65, c044 0.57 | Q26: merge | R26: shares_with_service_providers | T26: accept | V26: reviewed on the page; see decisions/page_answers_2026-10-15.json and resolutions_2026-10-15.yaml | W26: =IF(T26="accept",R26,U26)
A27: c025 | B27: 246 | C27: 111 | D27: 0.222 | E27: 0.4748 | F27: 0.669 | G27: (no heading) (41); arbitration (11); dispute resolution arbitration (9) | H27: legal_governance | I27: States that the privacy policy and related matters are governed by the laws of a specific jurisdiction, including the resolution of disputes and the authoritative version of the policy. | L27: The Privacy Policy is governed by the laws of a specific state. | M27: The company states that the policy and use of the site are governed by New York law. | N27: The company states that disputes over privacy or the privacy policy will be governed by the law of a specific jurisdiction. | O27: term_definition (12), legal_governance (10), dispute_resolution (9), service_location (4), third_party_rights (4) | P27: c036 0.51, c038 0.49, c037 0.46 | Q27: keep | R27: governing_law_and_disputes | T27: accept | V27: reviewed on the page; see decisions/page_answers_2026-10-15.json and resolutions_2026-10-15.yaml | W27: =IF(T27="accept",R27,U27)
A28: c026 | B28: 242 | C28: 132 | D28: 0.264 | E28: 0.5675 | F28: 0.56 | G28: (no heading) (28); data retention (9); retention period (5) | H28: data_retention_policy | I28: States that the company retains personal information for a specified period, typically as long as necessary for the original purpose or as required by law, and may retain it for archival or legal purposes even after account closure. | L28: The company retains personal information as long as necessary for the original purpose or as required by law. | M28: The company retains collected information as long as the user's account is active and as required by legal obligations. | N28: The company may retain personal information for a longer period if required or permitted by law. | O28: data_retention_policy (28), data_retention (23), data_retention_period (18), data_deletion_policy (8), deletion_policy (6) | P28: c065 0.39, c068 0.35, c054 0.33 | Q28: keep | R28: states_retention_period | T28: accept | V28: reviewed on the page; see decisions/page_answers_2026-10-15.json and resolutions_2026-10-15.yaml | W28: =IF(T28="accept",R28,U28)
A29: c027 | B29: 241 | C29: 177 | D29: 0.354 | E29: 0.6535 | F29: 0.354 | G29: (no heading) (39); log files (27); privacy policy (7) | H29: data_non_linking_policy | I29: States that the company does not link collected technical information, such as IP addresses, to personally identifiable information, with some exceptions for compliance or protection. | J29: mixed | K29: data_non_linking_policy, non_identification, data_collection_policy | L29: The company does not link collected IP addresses and other information to personally identifiable information. | M29: The company does not normally link IP addresses to personally identifiable information, but may do so to enforce compliance or protect its service. | N29: The company does not link IP addresses to personally identifiable information. | O29: data_linking_policy (23), non_identification (11), data_collection_policy (8), data_linking (6), data_non_storage (6) | P29: c039 0.67, c062 0.60, c070 0.59 | Q29: merge | R29: tracking_data_not_linked_to_identity | T29: accept | V29: reviewed on the page; see decisions/page_answers_2026-10-15.json and resolutions_2026-10-15.yaml | W29: =IF(T29="accept",R29,U29)
A30: c028 | B30: 231 | C30: 174 | D30: 0.348 | E30: 0.7818 | F30: 0.287 | G30: (no heading) (44); what do we use your information for (29); how do we use your information (10) | H30: uses_data_to_improve_website | I30: States that the company uses collected information to improve the website, services, and user experience. | L30: The company uses collected information to improve the sites and services. | M30: The company uses collected information to improve their website and personalize your experience. | N30: The company uses collected information to improve the website to better serve users. | O30: data_use (53), website_improvement (19), data_collection_purpose (14), service_improvement (14), customer_service_improvement (12) | P30: c057 0.72, c008 0.61, c001 0.42 | Q30: keep | R30: uses_data_to_improve_services | T30: accept | V30: reviewed on the page; see decisions/page_answers_2026-10-15.json and resolutions_2026-10-15.yaml | W30: =IF(T30="accept",R30,U30)
A31: c029 | B31: 230 | C31: 186 | D31: 0.372 | E31: 0.6117 | F31: 0.37 | G31: (no heading) (66); changes to our privacy policy (10); privacy policy (8) | H31: consent_through_use | I31: States that using the website or service implies or signifies the user's consent to the privacy policy or the collection and use of their information. | L31: The company states that using the site implies consent to the privacy policy. | M31: The company states that by using the site, users signify their acceptance of the privacy policy. | N31: The company states that by using the Services, users consent to the collection and use of their information as outlined in the Privacy Policy. | O31: user_consent (36), user_agreement (24), consent_implied (12), consent_through_use (11), user_acceptance (11) | P31: c073 0.50, c037 0.38, c011 0.35 | Q31: keep | R31: consent_by_use | T31: accept | V31: reviewed on the page; see decisions/page_answers_2026-10-15.json and resolutions_2026-10-15.yaml | W31: =IF(T31="accept",R31,U31)
A32: c030 | B32: 228 | C32: 155 | D32: 0.31 | E32: 0.6526 | F32: 0.388 | G32: (no heading) (42); privacy policy (5); use of information collected (4) | H32: shares_information_with_affiliates_partners | I32: States that the company may share personal information with affiliates, subsidiaries, business partners, or related entities for various business purposes, including fulfilling requests, marketing, and operational needs. | L32: The company may share personal information with business partners to fulfill requests for products or services. | M32: The company states that personal information may be shared with partners providing services on their behalf. | N32: The company shares personal information with other entities and affiliates within the family of companies for business and operational purposes. | O32: data_sharing (36), data_sharing_purpose (9), information_sharing (8), affiliate_sharing (6), disclosure_to_affiliates (5) | P32: c024 0.78, c044 0.63, c033 0.49 | Q32: keep | R32: shares_with_affiliates_and_partners | T32: accept | V32: reviewed on the page; see decisions/page_answers_2026-10-15.json and resolutions_2026-10-15.yaml | W32: =IF(T32="accept",R32,U32)
A33: c031 | B33: 215 | C33: 95 | D33: 0.19 | E33: 0.4998 | F33: 0.692 | G33: (no heading) (16); privacy complaints (9); rights of the parties concerned (9) | H33: disclose_data_rights | I33: States that the company informs users of their rights to access, complain, or request changes to their personal data held by the company. | L33: The company allows individuals to complain to a data protection authority about their collection and use of personal information. | M33: The company discloses that individuals have the right to raise a complaint with the data protection regulator. | N33: The company discloses that individuals have the right to request access to, deletion of, or correction of their personal data held by the company. | O33: disclose_right (30), access_right (11), disclose_rights (11), complaint_right (5), data_access_right (4) | P33: c014 0.46, c012 0.43, c003 0.39 | Q33: keep | R33: disclose_data_rights | T33: accept | V33: reviewed on the page; see decisions/page_answers_2026-10-15.json and resolutions_2026-10-15.yaml | W33: =IF(T33="accept",R33,U33)
A34: c032 | B34: 213 | C34: 152 | D34: 0.304 | E34: 0.6598 | F34: 0.382 | G34: (no heading) (43); personal information (9); registration (6) | H34: uses_contact_information | I34: States that the company uses contact information to communicate with users about products, services, promotions, and administrative matters, but not for marketing unless consent is given. | L34: The company uses information to contact users about relevant services and offers. | M34: The company uses personal information to contact users about products, services, upcoming events, and offers from itself and third parties. | N34: The company uses contact information to communicate about administrative notices, new product offerings, and relevant communications. | O34: data_use (30), contact_use (13), disclosing_practice (7), data_use_purpose (7), communication_purpose (6) | P34: c006 0.67, c071 0.60, c048 0.49 | Q34: merge | R34: sends_marketing_communications | T34: accept | V34: reviewed on the page; see decisions/page_answers_2026-10-15.json and resolutions_2026-10-15.yaml | W34: =IF(T34="accept",R34,U34)
A35: c033 | B35: 206 | C35: 148 | D35: 0.296 | E35: 0.6907 | F35: 0.502 | G35: (no heading) (27); business transfers (11); sharing information (5) | H35: business_transfer_data | I35: States that the company may transfer personal information to third parties in the event of a business transaction such as a merger, acquisition, sale, or reorganization, but does not include routine data sharing or transfers for operational purposes. | L35: The company may transfer personal information to an acquiring or merging party as part of a business transaction. | M35: The company may transfer personal information as part of a merger, acquisition, or sale of assets. | N35: The company may transfer personal information to a third party in the event of a merger, acquisition, reorganization, or sale of assets. | O35: business_transfer (13), data_transfer (9), asset_transfer (5), business_transfer_disclosure (4), data_transfer_on_acquisition (4) | P35: c040 0.50, c030 0.49, c024 0.48 | Q35: keep | R35: transfers_data_in_business_transfer | T35: accept | V35: reviewed on the page; see decisions/page_answers_2026-10-15.json and resolutions_2026-10-15.yaml | W35: =IF(T35="accept",R35,U35)
A36: c034 | B36: 200 | C36: 169 | D36: 0.338 | E36: 0.7751 | F36: 0.464 | G36: (no heading) (44); cookies (32); use of cookies (11) | H36: disabling_cookies_consequences | I36: Warns that disabling cookies may affect the functionality, access to features, or performance of the website. | L36: The company notes that refusing cookies may affect the functionality of the website. | M36: Disabling cookies may prevent some parts of the website from operating correctly and may limit access to some features or services. | N36: You are always free to decline any cookies we use by adjusting the settings of your browser, but some products, services or features might not be available or operate properly if cookies are not enabled. | O36: stating_limitation (13), user_control (9), disabling_consequence (7), functionality_warning (7), cookie_disabling (6) | P36: c022 0.74, c035 0.56, c053 0.40 | Q36: keep | R36: warns_disabling_cookies_limits_site | T36: accept | V36: reviewed on the page; see decisions/page_answers_2026-10-15.json and resolutions_2026-10-15.yaml | W36: =IF(T36="accept",R36,U36)
A37: c035 | B37: 195 | C37: 124 | D37: 0.248 | E37: 0.6993 | F37: 0.566 | G37: (no heading) (20); doubleclick dart cookie (18); cookies (10) | H37: provides_opt_out_options | I37: States that the company provides users with various options to opt out of specific types of data collection or advertising, including links, methods, and instructions for opting out of cookies, interest-based advertising, and mobile tracking. | L37: The company provides a way for users to opt out of the DART cookie use. | M37: Users may opt out of the use of the DART cookie by visiting the advertising opt-out page. | N37: The company provides a link for users to opt out of interest-based advertising using the DoubleClick cookie. | O37: user_opt_out (25), opt_out_provision (22), opt_out_link (18), dart_cookie_opt_out (12), granting_right (10) | P37: c005 0.80, c022 0.69, c046 0.59 | Q37: keep | R37: opt_out_of_tracking_or_ads | T37: accept | V37: reviewed on the page; see decisions/page_answers_2026-10-15.json and resolutions_2026-10-15.yaml | W37: =IF(T37="accept",R37,U37)
A38: c036 | B38: 193 | C38: 148 | D38: 0.296 | E38: 0.692 | F38: 0.449 | G38: (no heading) (42); links (11); online privacy policy only (11) | H38: policy_scope_limitation | I38: States that the company's privacy policy applies only to its own website and not to other linked, external, or third-party websites or services. | L38: The company's privacy policy applies only to its own website and not to other linked websites. | M38: The company's privacy policy does not apply to external websites. | N38: The company's privacy policy does not apply to third-party websites or services. | O38: policy_scope (49), policy_exclusion (23), policy_non_applicability (10), policy_coverage_limitation (7), policy_limitation (6) | P38: c009 0.60, c064 0.55, c023 0.54 | Q38: keep | R38: scope_excludes_third_party_sites | T38: accept | V38: reviewed on the page; see decisions/page_answers_2026-10-15.json and resolutions_2026-10-15.yaml | W38: =IF(T38="accept",R38,U38)
A39: c037 | B39: 184 | C39: 103 | D39: 0.206 | E39: 0.4466 | F39: 0.589 | G39: (no heading) (54); terms and services bookplate creator (6); social media disclaimer (5) | H39: content_and_usage_restrictions | I39: States that users must not use the site or its content in certain ways, including reproducing, modifying, or distributing content without permission, and must not use the site if they do not agree to the terms or privacy policy. | J39: mixed | K39: content_restriction, disagreement_consequence | L39: The company states that users are not allowed to submit content that violates or infringes the rights of others. | M39: The company states that users may not modify, copy, reproduce, create derivative works, republish, display, upload, post, transmit, or distribute content without prior written consent. | N39: The company states that if users do not agree with the terms, they should not use the site. | O39: disagreement_action (8), ownership_claim (8), content_restriction (7), disagreement_consequence (5), content_ownership (4) | P39: c025 0.46, c019 0.44, c018 0.40 | Q39: keep | R39: content_and_usage_restrictions | T39: accept | V39: reviewed on the page; see decisions/page_answers_2026-10-15.json and resolutions_2026-10-15.yaml | W39: =IF(T39="accept",R39,U39)
A40: c038 | B40: 180 | C40: 114 | D40: 0.228 | E40: 0.56 | F40: 0.497 | G40: (no heading) (40); childrens online privacy protection act compliance (10); california online privacy protection act compliance (7) | H40: compliance_with_laws_and_standards | I40: States that the company complies with specific laws, regulations, or industry standards related to privacy and data protection. | L40: The company participates in and has certified compliance with the EU-U.S. Privacy Shield Framework. | M40: The company complies with the Children's Online Privacy Protection Act and all other applicable laws. | N40: The company operates its website in compliance with the Children's Online Privacy Protection Act (COPPA). | O40: compliance_statement (15), legal_compliance (15), compliance_with_law (5), safe_harbor_principles (5), third_party_seal (5) | P40: c017 0.55, c025 0.49, c007 0.47 | Q40: keep | R40: complies_with_laws_and_programs | T40: accept | V40: reviewed on the page; see decisions/page_answers_2026-10-15.json and resolutions_2026-10-15.yaml | W40: =IF(T40="accept",R40,U40)
A41: c039 | B41: 180 | C41: 144 | D41: 0.288 | E41: 0.7122 | F41: 0.42 | G41: (no heading) (38); cookies (34); log files (8) | H41: cookie_non_identification | I41: States that the company does not use cookies to collect, store, or link to personally identifiable information. | L41: The company does not use cookies to collect personally identifiable information. | M41: The company does not use cookies to collect users' personally identifiable information. | N41: The company states that cookies do not collect personally identifiable information. | O41: stating_limitation (10), cookie_policy (10), cookie_usage (9), cookie_use (9), cookie_limitation (7) | P41: c027 0.67, c023 0.55, c062 0.53 | Q41: merge | R41: tracking_data_not_linked_to_identity | T41: accept | V41: reviewed on the page; see decisions/page_answers_2026-10-15.json and resolutions_2026-10-15.yaml | W41: =IF(T41="accept",R41,U41)
A42: c040 | B42: 176 | C42: 101 | D42: 0.202 | E42: 0.6656 | F42: 0.584 | G42: (no heading) (18); international transfer (6); where we store your personal data (5) | H42: data_transfer_to_us | I42: States that personal information may be transferred to, stored, or processed in the United States, often requiring user consent or agreement. | L42: The company states that personal information may be transferred to, stored, or processed in the USA. | M42: Personal data provided by users outside the United States will be transferred to the United States. | N42: The company may store and process collected information in any of the countries where it operates. | O42: data_transfer (39), data_storage_location (15), data_location (11), data_processing_location (7), user_consent (6) | P42: c033 0.50, c024 0.27, c030 0.23 | Q42: keep | R42: transfers_data_internationally | T42: accept | V42: reviewed on the page; see decisions/page_answers_2026-10-15.json and resolutions_2026-10-15.yaml | W42: =IF(T42="accept",R42,U42)
...

Sheet Types
A1: Type id | B1: Name | C1: Definition | D1: Positive example 1 | E1: Positive example 2 | F1: Near miss | G1: Severity weight | H1: Section hint | I1: Label source | J1: Seeds | K1: Source clusters (proposed) | L1: Claims (your decisions) | M1: Notes
A2: states_information_required_to_register | B2: states_information_required_to_register | C2: States that users must create an account or register to use the service or parts of it, and which personal information they must provide to do so (mandatory fields), as opposed to information they may choose to give. | D2: The company asks for specific personal information when users register. | E2: The company requires users to provide personal information during registration. | F2: The company collects personal information when users register or place an order on the site. | G2: 1.5 | H2: in the first half of the document | I2: First Party Collection/Use :: Collection Mode = Explicit & User Type = User with account | J2: first_party_collection_use | K2: c021 | L2: =SUMIF(Clusters!$W$2:$W$75,A2,Clusters!$B$2:$B$75) | M2: GDPR Art. 13(2)(e): whether providing the data is a requirement; definition widened after the coverage check; auto-filled, check: positive_examples, near_miss, section_hint
A3: collects_usage_data_automatically | B3: collects_usage_data_automatically | C3: States that the company automatically collects technical or usage data about visits (IP address, browser, pages viewed, log files) without the user entering it. | D3: The company collects information about the number of users visiting the website and the number of pages viewed. | E3: The company uses log files to collect various types of data for analyzing trends, administering the site, tracking user movement, and gathering demographic information. | F3: The company uses web beacons to track user visits and email opens for analytics purposes. | G3: 1.5 | H3: in the first half of the document | I3: First Party Collection/Use :: Collection Mode = Implicit & Personal Information Type = User online activities First Party Collection/Use :: Collection Mode = Implicit & Personal Information Type = IP address and device IDs First Party Collection/Use :: Collection Mode = Implicit & Personal Information Type = Computer information | J3: first_party_collection_use | K3: c001, c060 | L3: =SUMIF(Clusters!$W$2:$W$75,A3,Clusters!$B$2:$B$75) | M3: CCPA 1798.100(b): categories collected; auto-filled, check: positive_examples, near_miss, section_hint
A4: uses_cookies | B4: uses_cookies | C4: States that the company sets cookies or similar tracking technologies and what it uses them for (recognising users, remembering preferences, tracking visits). | D4: The company uses cookies to identify which pages on their website have been accessed. | E4: The company uses cookies and similar tracking technologies to access or store information. | F4: The company mentions that third-party advertising and marketing partners may use their own cookies. | G4: 1 | H4: under a heading like 'cookies', in the first half of the document | I4: First Party Collection/Use :: Personal Information Type = Cookies and tracking elements | J4: first_party_collection_use | K4: c000, c050 | L4: =SUMIF(Clusters!$W$2:$W$75,A4,Clusters!$B$2:$B$75) | M4: auto-filled, check: positive_examples, near_miss, section_hint
A5: uses_web_beacons | B5: uses_web_beacons | C5: States that the company uses web beacons, pixel tags or clear GIFs (on pages or in emails) to collect information about visits or email opens; plain cookie statements are uses_cookies. | D5: The company uses web beacons to track user visits and email opens for analytics purposes. | E5: The company uses web beacons to track which visitors interact with specific elements on web pages or emails. | F5: The company collects information about the number of users visiting the website and the number of pages viewed. | G5: 1 | H5: in the first half of the document | I5: teacher | J5: first_party_collection_use | K5: c052 | L5: =SUMIF(Clusters!$W$2:$W$75,A5,Clusters!$B$2:$B$75) | M5: auto-filled, check: positive_examples, near_miss, section_hint
A6: tracking_data_not_linked_to_identity | B6: tracking_data_not_linked_to_identity | C6: States that cookies, IP addresses or other technical data are not linked to, or not used to identify, the person (except where stated). | D6: The company does not link collected IP addresses and other information to personally identifiable information. | E6: The company does not use cookies to collect personally identifiable information. | F6: The company allows users to visit the site without providing personal information. | G6: 1 | H6: in the first half of the document | I6: teacher | J6: first_party_collection_use | K6: c027, c039 | L6: =SUMIF(Clusters!$W$2:$W$75,A6,Clusters!$B$2:$B$75) | M6: c027 was flagged mixed by the teacher (non-linking vs non-identification); both are the same promise; auto-filled, check: positive_examples, near_miss, section_hint
A7: defines_personal_information | B7: defines_personal_information | C7: Defines terms used in the policy, most often what counts as personal (personally identifiable) information or anonymous information. | D7: The company defines personal information as personally identifiable information about an individual. | E7: The company defines Personal Information as data that can identify an individual. | F7: The company discloses that the privacy policy covers the collection, use, and choices about personal information collected on or through the services. | G7: 1 | H7: near the start of the document | I7: teacher | J7: other | K7: c069 | L7: =SUMIF(Clusters!$W$2:$W$75,A7,Clusters!$B$2:$B$75) | M7: definition widened after the coverage check; auto-filled, check: positive_examples, near_miss, section_hint
A8: uses_data_to_improve_services | B8: uses_data_to_improve_services | C8: States that collected information is used to analyse, maintain or improve the website, services or user experience. | D8: The company uses collected information to improve the sites and services. | E8: The company uses collected information to improve their website and personalize your experience. | F8: The company uses data to personalize and tailor the user experience and products. | G8: 1 | H8: under a heading like 'what do we use your information for', in the first half of the document | I8: First Party Collection/Use :: Purpose = Analytics/Research | J8: first_party_collection_use | K8: c028 | L8: =SUMIF(Clusters!$W$2:$W$75,A8,Clusters!$B$2:$B$75) | M8: auto-filled, check: positive_examples, near_miss, section_hint
A9: uses_data_to_personalize | B9: uses_data_to_personalize | C9: States that collected information is used to personalise or customise content, offers or the user's experience. | D9: The company uses data to personalize and tailor the user experience and products. | E9: The company uses collected information to personalize the user experience. | F9: The company uses collected information to improve the sites and services. | G9: 1 | H9: under a heading like 'what do we use your information for', in the first half of the document | I9: First Party Collection/Use :: Purpose = Personalization/Customization | J9: first_party_collection_use | K9: c057 | L9: =SUMIF(Clusters!$W$2:$W$75,A9,Clusters!$B$2:$B$75) | M9: auto-filled, check: positive_examples, near_miss, section_hint
A10: sends_marketing_communications | B10: sends_marketing_communications | C10: States that the company uses contact details (mainly email) to send newsletters, promotions or other marketing communications about its own products and services. | D10: The company may send promotional emails about new products or special offers. | E10: The company uses information to contact users about relevant services and offers. | F10: The company collects information when users participate in contests or promotions. | G10: 1 | H10: in the first half of the document | I10: First Party Collection/Use :: Purpose = Marketing | J10: first_party_collection_use | K10: c006, c032 | L10: =SUMIF(Clusters!$W$2:$W$75,A10,Clusters!$B$2:$B$75) | M10: auto-filled, check: positive_examples, near_miss, section_hint
A11: does_not_sell_or_share | B11: does_not_sell_or_share | C11: States that the company does not sell, rent, trade or share personal information (or email addresses) with third parties, apart from any stated exceptions. | D11: The company does not sell, rent, or trade personal information to third parties. | E11: The company does not sell, trade, share, or rent the user's email address to anyone. | F11: The company does not link collected IP addresses and other information to personally identifiable information. | G11: 1.5 | H11: in the first half of the document | I11: Third Party Sharing/Collection :: Does/Does Not = Does Not | J11: third_party_sharing_collection | K11: c004, c043 | L11: =SUMIF(Clusters!$W$2:$W$75,A11,Clusters!$B$2:$B$75) | M11: CCPA 1798.115/1798.120: disclosure of sale; the negative form is the common one in this pre-2020 corpus; auto-filled, check: positive_examples, near_miss, section_hint
A12: shares_with_service_providers | B12: shares_with_service_providers | C12: States that personal information is shared with, or processed by, third-party service providers acting on the company's behalf (payment, delivery, hosting, mailing). | D12: The company may share personal information with third parties hired to perform services, under strict conditions. | E12: The company uses third party service providers to perform various functions on its behalf. | F12: The company may share personal information with business partners to fulfill requests for products or services. | G12: 1.5 | H12: in the first half of the document | I12: Third Party Sharing/Collection :: Purpose = Basic service/feature & Does/Does Not = Does Third Party Sharing/Collection :: Purpose = Service operation and security & Does/Does Not = Does | J12: third_party_sharing_collection | K12: c024, c055 | L12: =SUMIF(Clusters!$W$2:$W$75,A12,Clusters!$B$2:$B$75) | M12: GDPR Art. 13(1)(e): recipients or categories of recipients; auto-filled, check: positive_examples, near_miss, section_hint
A13: shares_with_affiliates_and_partners | B13: shares_with_affiliates_and_partners | C13: States that personal information may be shared with affiliates, subsidiaries or business partners, and for what purposes. | D13: The company may share personal information with business partners to fulfill requests for products or services. | E13: The company states that personal information may be shared with partners providing services on their behalf. | F13: The company may share personal information with third parties hired to perform services, under strict conditions. | G13: 1.5 | H13: in the first half of the document | I13: Third Party Sharing/Collection :: Third Party Entity = Other part of company/affiliate | J13: third_party_sharing_collection | K13: c030 | L13: =SUMIF(Clusters!$W$2:$W$75,A13,Clusters!$B$2:$B$75) | M13: GDPR Art. 13(1)(e): recipients; auto-filled, check: positive_examples, near_miss, section_hint
... A47: provides_privacy_contact | B47: provides_privacy_contact | C47: Tells readers how to contact the company about the policy or their information (email, address, phone, form, named contact person). | D47: The company provides a contact method for questions about the privacy policy or services. | E47: The company provides contact information for questions about privacy policy or practices. | F47: The company uses information to contact users about relevant services and offers. | G47: 1.5 | H47: in the second half of the document | I47: Other :: Other Type = Privacy contact information | J47: other | K47: c014, c048, c071 | L47: =SUMIF(Clusters!$W$2:$W$75,A47,Clusters!$B$2:$B$75) | M47: GDPR Art. 13(1)(a)-(b): contact details of the controller (and DPO). c048 and c071 had the same teacher name; auto-filled, check: positive_examples, near_miss, section_hint
A48: do_not_track_response | B48: do_not_track_response | C48: States whether and how the company responds to browser Do Not Track signals (most often that it does not). | D48: The company does not respond to browser 'Do Not Track' signals at this time. | E48: The company honors do not track signals. | F48: The company allows users to disable cookies through their web browser settings. | G48: 1 | H48: in or next to the cookies and tracking section, in the second half of the document | I48: Do Not Track | J48: do_not_track | L48: =SUMIF(Clusters!$W$2:$W$75,A48,Clusters!$B$2:$B$75) | M48: 35 claims from 29 of 500 documents, 31 of them HDBSCAN noise (too few for min cluster size 80); CalOPPA requires it for California, not GDPR/CCPA, so severity 1.0
A49: california_disclosure_rights | B49: california_disclosure_rights | C49: States the rights of California residents to learn which third parties received their information for direct marketing, and how to make the request. | D49: The company discloses that California residents can request a list of third parties to which personal information was disclosed for direct marketing purposes. | E49: California residents have the right to request a list of third parties to whom the company has disclosed personal information for direct marketing purposes. | F49: The company allows individuals to complain to a data protection authority about their collection and use of personal information. | G49: 1 | H49: near the end, under a heading like 'Your California Privacy Rights' | I49: International and Specific Audiences :: Audience Type = Californians | J49: international_specific_audiences | L49: =SUMIF(Clusters!$W$2:$W$75,A49,Clusters!$B$2:$B$75) | M49: 89 claims from 45 documents, 64 of them noise; California 'Shine the Light' (Civ. Code 1798.83), not CCPA, so severity 1.0
A50: data_collection_methods | B50: data_collection_methods | C50: States that the company collects personal information from users through various activities on the website, such as registration, placing orders, or providing information. | D50: The company collects personal information when users register or place an order on the site. | E50: The company collects various types of personal information from users, including contact details and demographic information. | F50: The company collects information about the number of users visiting the website and the number of pages viewed. | G50: 1.5 | H50: near the start of the document | I50: First Party Collection/Use :: Collection Mode = Explicit & Does/Does Not = Does | J50: first_party_collection_use | K50: c002 | L50: =SUMIF(Clusters!$W$2:$W$75,A50,Clusters!$B$2:$B$75) | M50: kept as its own item by the reviewer (group c002); severity and label source carried over from collects_information_users_provide; auto-filled, check: positive_examples, near_miss, section_hint
A51: data_use_for_services | B51: data_use_for_services | C51: States that the company uses collected personal information for providing products, services, processing orders, and customer support. | D51: The company uses collected personal information to provide products and services, process orders, and offer customer service. | E51: The company uses collected information to fulfill orders, provide quotes, process orders, notify about order status, prepare drawings, and provide information about offers or products. | F51: The company uses collected information to improve the sites and services. | G51: 1.5 | H51: in the first half of the document | I51: First Party Collection/Use :: Purpose = Basic service/feature | J51: first_party_collection_use | K51: c008 | L51: =SUMIF(Clusters!$W$2:$W$75,A51,Clusters!$B$2:$B$75) | M51: kept as its own item by the reviewer (group c008); severity and label source carried over from uses_data_to_provide_services; auto-filled, check: positive_examples, near_miss, section_hint
