Workbook

Sheet Read me
A1: Schema review workbook, genre: papers (plan task 3.4: merge, split and prune clusters to 40-60 types)
A3: Yellow columns are yours. Grey columns are computed (Clusters, Claims, Noise sample) or proposed by Claude.
A4: Clusters sheet, 'Your action' (dropdown): accept = take the proposed action and type as they are;
A5: keep = the cluster is one type (give it in 'Your type'); merge = it joins the type in 'Your type' with
A6: other clusters; split = it holds several types (list them in 'Your type', comma-separated);
A7: prune = not a genre type (say why in 'Notes'). A row left blank blocks the schema.
A8: Types sheet: the proposed types with every field the frozen schema needs. Edit any cell, delete rows,
A9: add rows. Type ids must match what the Clusters sheet points to. Examples are claim texts.
A10: Severity weight: 1.0 by default; 1.5 for privacy types that GDPR Art. 13/14 or CCPA require.
A11: Section hint: where peers usually state it (used by the ghost-paragraph view).
A12: Label source (privacy): OPP-115 values that count as a positive, one per line, written
A13: 'Category :: Attribute = Value' or just 'Category' (lines are alternatives; '&' joins attribute values that
... A22: Provenance: cluster_run=cluster_v1_s0, name_run=name_72b_papers_s0, naming=openai:openrouter.ai:qwen/qwen-2.5-72b-instruct@deepinfra/fp8, proposals=proposals_papers.yaml

Sheet Summary
A1: Check | B1: Value
A2: Clusters | B2: =COUNTA(Clusters!A2:A81)
A3: Clusters still undecided | B3: =SUMPRODUCT((Clusters!A2:A81<>"")*(Clusters!T2:T81=""))
A4: Clusters pruned (your decisions) | B4: =COUNTIF(Clusters!T2:T81,"prune")
A5: Claims in pruned clusters | B5: =SUMIF(Clusters!T2:T81,"prune",Clusters!B2:B81)
A6: Types on the Types sheet | B6: =COUNTA(Types!A2:A500)
A7: Types within 40-60? | B7: =IF(AND(B6>=40,B6<=60),"yes","no")
A8: Types missing a required field | B8: =SUMPRODUCT((Types!A2:A500<>"")*(((Types!C2:C500="")+(Types!D2:D500="")+(Types!E2:E500="")+(Types!F2:F500="")+(Types!H2:H500=""))>0))
A9: Seeds still undecided | B9: =COUNTBLANK(Seeds!E2:E35)
A10: Kept-or-merged clusters with no type given | B10: =SUMPRODUCT((Clusters!T2:T81<>"")*(Clusters!T2:T81<>"accept")*(Clusters!T2:T81<>"prune")*(Clusters!U2:U81=""))

Sheet Clusters
A1: Cluster | B1: Size | C1: Documents | D1: Document share | E1: Cohesion | F1: Position (0 first, 1 last) | G1: Top headings | H1: Teacher name | I1: Teacher definition | J1: Flags | K1: Split note | L1: Representative 1 | M1: Representative 2 | N1: Representative 3 | O1: Top extraction labels | P1: Nearest clusters (cosine) | Q1: Proposed action | R1: Proposed type | S1: Reason | T1: Your action | U1: Your type | V1: Notes | W1: Effective type
A2: c000 | B2: 2669 | C2: 290 | D2: 0.957 | E2: 0.3943 | F2: 0.447 | G2: introduction (330); abstract (182); related work (90) | H2: state_model_or_method_limitation | I2: States that the model, method, or approach has specific limitations or challenges, often related to performance, data, or specific application contexts. | L2: The authors discuss the limitations of pre-trained language models due to differences in word distributions between general and financial corpora. | M2: The authors describe a limitation of BERT in capturing structural information due to the lack of explicit order in its blocks. | N2: The authors state a limitation of their work related to the model's performance on certain categories. | O2: state_limitation (121), method_limitation (114), model_limitation (43), stating_limitation (42), performance_limitation (35) | P2: c053 0.40, c016 0.31, c049 0.19 | Q2: keep | R2: states_limitations_or_challenges | W2: =IF(T2="accept",R2,U2)
A3: c001 | B3: 1331 | C3: 227 | D3: 0.749 | E3: 0.428 | F3: 0.469 | G3: introduction (45); abstract (29); related work (22) | H3: model_architecture_description | I3: Describes the detailed structure and components of the neural network or model architecture, including layers, activation functions, and specific operations such as attention mechanisms, pooling, and convolutional layers. | L3: The authors describe the process of encoding sequences through a multi-head attention and feed-forward network. | M3: The authors detail the transformer encoder layers with sub-layers for multi-head self-attention and position-wise feed-forward networks. | N3: The authors describe the structure of the neural network, including the number of convolutional and fully-connected layers, and the properties of the activation functions and pooling operations. | O3: method_description (211), model_description (60), model_architecture (48), architecture_description (23), describe_method (17) | P3: c063 0.44, c051 0.43, c056 0.37 | Q3: merge | R3: describes_model_architecture | W3: =IF(T3="accept",R3,U3)
A4: c002 | B4: 1270 | C4: 235 | D4: 0.776 | E4: 0.4043 | F4: 0.497 | G4: evaluation metrics (54); introduction (47); abstract (43) | H4: describes_evaluation_metrics | I4: Describes the specific metrics or methods used to evaluate the performance of models or methods, including precision, recall, F1 score, and other quantitative or qualitative measures. | L4: The authors describe the evaluation method used in their experiments, referring to it as F1 score. | M4: The authors state that they compute accuracy, macro F1-score, and Cohen's kappa for performance evaluation. | N4: The authors use F1 score as the primary evaluation metric for their experiments. | O4: method_description (68), evaluation_method (54), evaluation_metrics (44), evaluation_metric (37), metric_description (33) | P4: c064 0.38, c038 0.37, c062 0.32 | Q4: keep | R4: describes_evaluation_metrics | W4: =IF(T4="accept",R4,U4)
A5: c003 | B5: 1065 | C5: 229 | D5: 0.756 | E5: 0.5189 | F5: 0.619 | G5: implementation details (47); experiments (38); hyperparameters (19) | H5: specifies_hyperparameters | I5: Describes the specific hyperparameters, such as learning rate, batch size, and optimizer, used during the training of models. | L5: The authors specify the parameters used during the fine-tuning process, such as the number of epochs, dropout probability, batch size, and learning rates. | M5: The authors set specific hyper-parameters for the WikiSQL model, including batch size, beam size, and learning rate. | N5: The authors specify the batch size, learning rate, and optimizer used for training the model. | O5: method_description (67), hyperparameter_tuning (23), training_duration (22), parameter_setting (21), training_details (17) | P5: c063 0.45, c019 0.43, c051 0.40 | Q5: merge | R5: specifies_hyperparameters | W5: =IF(T5="accept",R5,U5)
A6: c004 | B6: 938 | C6: 191 | D6: 0.63 | E6: 0.4501 | F6: 0.53 | G6: introduction (56); abstract (45); conclusion (32) | H6: performance_and_efficiency | I6: States that the authors evaluate, compare, or describe the computational efficiency, time complexity, or resource usage of their methods or models, often in comparison to existing approaches. | L6: The authors highlight the computational efficiency of their method compared to a variant. | M6: The authors state that their proposed method has lower computational overhead compared to previous methods. | N6: The authors highlight the computational efficiency of the Euler kernel compared to traditional kernels. | O6: method_description (22), performance_comparison (12), performance_report (10), report_complexity (10), training_time (10) | P6: c021 0.38, c038 0.36, c043 0.36 | Q6: keep | R6: reports_computational_cost | W6: =IF(T6="accept",R6,U6)
A7: c005 | B7: 848 | C7: 214 | D7: 0.706 | E7: 0.6219 | F7: 0.445 | G7: datasets (74); introduction (35); dataset (33) | H7: describe_datasets | I7: Describes the datasets used in the experiments, including their sources, characteristics, and content. | L7: The authors describe the dataset they use for their experiments. | M7: The authors describe the datasets used in their experiments and their characteristics. | N7: The authors describe the dataset used in their experiments, including its source, content, and annotations. | O7: data_description (133), dataset_description (89), data_source (29), data_usage (25), describe_method (23) | P7: c054 0.71, c018 0.56, c025 0.46 | Q7: keep | R7: describes_datasets | W7: =IF(T7="accept",R7,U7)
A8: c006 | B8: 727 | C8: 151 | D8: 0.498 | E8: 0.3597 | F8: 0.446 | G8: abstract (20); related work (16); introduction (13) | H8: assumption_and_distribution | I8: States that the authors make assumptions about the distributions of variables, often specifying the type of distribution or the conditions under which these distributions are used. | L8: The authors assume a random variable follows a distribution from the exponential family with respect to a base measure. | M8: The authors assume a known distribution for a variable in the model. | N8: The authors assume that elements of each set are i.i.d. samples from an underlying distribution. | O8: method_description (56), assumption_description (9), definition (9), assumption (7), data_assumption (5) | P8: c033 0.40, c026 0.33, c037 0.27 | Q8: keep | R8: states_modeling_assumptions | W8: =IF(T8="accept",R8,U8)
A9: c007 | B9: 662 | C9: 233 | D9: 0.769 | E9: 0.5727 | F9: 0.642 | G9: conclusion (150); introduction (50); conclusions (31) | H9: suggests_future_work | I9: States that the authors propose or plan future research directions, enhancements, or investigations related to their current work. | L9: The authors suggest future work on the framework. | M9: The authors suggest future work could include expanding the dataset and testing further enhancements. | N9: The authors suggest a direction for future research to integrate meta-learning and fine-tuning. | O9: future_work (148), future_research (39), future_work_plan (20), future_direction (14), future_investigation (10) | P9: c058 0.44, c020 0.41, c015 0.35 | Q9: keep | R9: suggests_future_work | W9: =IF(T9="accept",R9,U9)
A10: c008 | B10: 539 | C10: 64 | D10: 0.211 | E10: 0.4351 | F10: 0.401 | G10: preliminaries (28); reinforcement learning (22); environment (14) | H10: mdp_component_definition | I10: Defines or describes components of a Markov Decision Process (MDP), including states, actions, transition functions, reward functions, and initial state distributions. | L10: The authors define the action value function of a policy in terms of a trajectory generated by rolling out in the environment following the policy. | M10: The authors define the state-action distribution for a policy in an MDP. | N10: The authors describe the transition function, reward function, initial state distribution, and discount factor as components of the MDP. | O10: method_description (20), definition (13), reward_definition (8), reward_function (8), mdp_description (8) | P10: c012 0.54, c066 0.35, c010 0.35 | Q10: merge | R10: defines_task_or_problem_setting | W10: =IF(T10="accept",R10,U10)
A11: c009 | B11: 531 | C11: 64 | D11: 0.211 | E11: 0.624 | F11: 0.702 | G11: proof of theorem (59); proof of lemma (33); proof of proposition (30) | H11: provides_lemma_proof | I11: States that the authors provide, prove, or use lemmas in the context of proving theorems or other mathematical statements, often detailing the methods and steps involved. | L11: The authors provide a proof for Theorem [ref] that relies on an auxiliary result. | M11: The authors prove a lemma by leveraging equations and conditions. | N11: The authors provide a proof for a lemma. | O11: lemma_statement (25), proof_method (23), proof_conclusion (20), proof_completion (14), proof_provision (13) | P11: c074 0.71, c017 0.63, c015 0.56 | Q11: merge | R11: proves_or_derives | W11: =IF(T11="accept",R11,U11)
A12: c010 | B12: 491 | C12: 135 | D12: 0.446 | E12: 0.3863 | F12: 0.383 | G12: introduction (40); abstract (17); conclusion (11) | H12: task_description | I12: Describes the specific tasks, subtasks, or objectives of the research, including their nature and scope, but not the methods or results. | L12: The authors describe the goal of the task as classifying a term as either literal or euphemistic. | M12: The authors define the entity linking task as finding a unique identity for each mention in a document. | N12: The authors describe the main task as a multi-class token classification task. | O12: task_description (65), method_description (49), task_definition (14), describe_method (7), task_proposal (6) | P12: c026 0.52, c069 0.49, c066 0.41 | Q12: merge | R12: defines_task_or_problem_setting | W12: =IF(T12="accept",R12,U12)
A13: c011 | B13: 439 | C13: 190 | D13: 0.627 | E13: 0.5319 | F13: 0.397 | G13: related work (57); introduction (30); abstract (9) | H13: relate_to_prior_work | I13: Relates the current work to previous research, methods, or findings in the field, often by citing specific studies or approaches. | L13: The authors relate their work to previous attempts found in the literature. | M13: The authors relate their work to previous methods for solving similar problems. | N13: The authors relate their work to another study that used a similar augmentation method. | O13: external_context (41), relate_to_other_work (23), relate_to_prior_work (21), related_work (19), describe_data_method (8) | P13: c016 0.62, c040 0.49, c041 0.48 | Q13: merge | R13: reviews_prior_work | W13: =IF(T13="accept",R13,U13)
... A24: c022 | B24: 306 | C24: 114 | D24: 0.376 | E24: 0.4928 | F24: 0.513 | G24: abstract (15); introduction (15); (no heading) (11) | H24: implementation_details | I24: Describes the specific tools, libraries, or software packages used by the authors for implementing their methods or systems. | L24: The authors use a specific software library for their implementation. | M24: The authors use a specific library for the implementation of the MLMs. | N24: The authors describe the software package used for implementing the methodology. | O24: implementation_details (13), method_description (10), tool_usage (10), implementation_description (9), tool_description (7) | P24: c044 0.53, c071 0.53, c069 0.50 | Q24: keep | R24: names_software_and_libraries | W24: =IF(T24="accept",R24,U24)
A25: c023 | B25: 299 | C25: 135 | D25: 0.446 | E25: 0.6835 | F25: 0.531 | G25: abstract (38); conclusion (27); introduction (27) | H25: performance_comparison | I25: Reports that the authors' method, approach, or system outperforms other methods, baselines, or state-of-the-art techniques in terms of various performance metrics or tasks. | J25: duplicate_name | L25: The authors report that their method outperforms other methods on the task. | M25: The authors report that their proposed method outperforms the state-of-the-art baselines in terms of various performance metrics. | N25: The authors state that their best model outperforms a state-of-the-art model. | O25: performance_comparison (31), performance_report (28), performance_claim (23), performance_improvement (22), evaluation_result (16) | P25: c036 0.69, c038 0.51, c077 0.50 | Q25: merge | R25: reports_outperforming_others | W25: =IF(T25="accept",R25,U25)
A26: c024 | B26: 290 | C26: 81 | D26: 0.267 | E26: 0.4259 | F26: 0.422 | G26: introduction (19); network graphs (10); abstract (8) | H26: graph_construction_description | I26: Describes the construction of graphs, including the definition of nodes, edges, and the methods used to connect them, often in the context of document or data representation. | L26: The authors describe the construction of a document graph with nodes representing paragraphs and a fusion node. | M26: The authors describe how nodes in the document graph are connected based on shared entities. | N26: The authors describe the construction of a weighted graph using a three parts algorithm and an edge weight scheme. | O26: method_description (40), graph_description (10), data_description (5), process_description (5), transformation_description (4) | P26: c076 0.52, c069 0.41, c026 0.40 | Q26: merge | R26: describes_method_details | W26: =IF(T26="accept",R26,U26)
A27: c025 | B27: 264 | C27: 114 | D27: 0.376 | E27: 0.5172 | F27: 0.558 | G27: data (11); dataset (11); datasets (9) | H27: data_split_description | I27: Describes the division of datasets into training, validation, and test sets, including the proportions or specific numbers of data points used for each set. | L27: The authors describe the division of the dataset into training, validation, and test sets. | M27: The authors divide the data set into training, validation, and testing sets with specified proportions. | N27: The authors describe the division of the dataset into training, validation, and testing sets. | O27: data_split (23), data_splitting (12), data_division (8), data_usage (8), method_description (5) | P27: c005 0.46, c054 0.43, c075 0.38 | Q27: keep | R27: describes_data_split | W27: =IF(T27="accept",R27,U27)
A28: c026 | B28: 264 | C28: 57 | D28: 0.188 | E28: 0.4557 | F28: 0.441 | G28: introduction (17); mode declarations (16); references for functional tests (11) | H28: defines_predicates_and_relations | I28: Describes the logical structure, predicates, and relationships used in the computational model or data representation, including modes, conditions, and categories. | L28: The authors declare the mode of a predicate as an identity or inverse relationship with another predicate. | M28: The authors specify the mode of a predicate that takes a variable and a constant as arguments. | N28: The authors define a clause as a rule with a head atom and body atoms. | O28: mode_declaration (13), describing_data_or_method (10), definition (5), description_of_data (4), representation_method (4) | P28: c066 0.56, c030 0.55, c010 0.52 | Q28: merge | R28: describes_method_details | W28: =IF(T28="accept",R28,U28)
A29: c027 | B29: 257 | C29: 82 | D29: 0.271 | E29: 0.4792 | F29: 0.463 | G29: abstract (8); discussion on the choice of test function for miw (6); conclusion (5) | H29: optimization_method_description | I29: Describes the methods and techniques used by the authors to solve optimization problems, including specific algorithms, conditions, and mathematical operations. | L29: The authors state that the optimization process uses Nesterov's method to iteratively solve for a placement that minimizes both HPWL and density costs. | M29: The authors aim to solve the bilevel optimization using alternating stochastic gradient descent updates. | N29: The authors use the primal-dual decomposition method to solve the optimization problem. | O29: method_description (21), optimization_problem (11), problem_description (6), approximation_method (6), describe_data_or_method (5) | P29: c044 0.31, c050 0.30, c019 0.24 | Q29: merge | R29: describes_training_procedure | W29: =IF(T29="accept",R29,U29)
A30: c028 | B30: 255 | C30: 51 | D30: 0.168 | E30: 0.5018 | F30: 0.496 | G30: abstract (9); introduction (8); hierarchical clustering (7) | H30: clustering_method_description | I30: Describes the specific clustering methods or algorithms used by the authors, including details such as k-means, hierarchical clustering, and the criteria or parameters for clustering. | L30: The authors construct unsupervised clusters using k-means clustering for Cl-InfoNCE. | M30: The authors describe a pairwise clustering procedure with a threshold that determines whether two estimates belong to the same cluster. | N30: The authors use k-means clustering to group student answers into clusters. | O30: method_description (32), clustering_method (7), method_proposal (7), method_detail (5), method_application (4) | P30: c056 0.27, c045 0.25, c032 0.24 | Q30: merge | R30: describes_method_details | W30: =IF(T30="accept",R30,U30)
A31: c029 | B31: 246 | C31: 109 | D31: 0.36 | E31: 0.5454 | F31: 0.611 | G31: results (10); introduction (6); abstract (6) | H31: visualize_results | I31: Describes that the authors use various visualization techniques, such as graphs, heat maps, and figures, to illustrate the results, performance, or effectiveness of their methods or models. | L31: The authors visualize results using bar graphs. | M31: The authors use a visualization technique to show the effectiveness of their method. | N31: The authors visualize the result of their method in a figure. | O31: data_visualization (15), figure_reference (10), method_description (10), visualization_description (6), visualization_method (6) | P31: c061 0.49, c024 0.30, c015 0.24 | Q31: keep | R31: visualizes_results | W31: =IF(T31="accept",R31,U31)
A32: c030 | B32: 239 | C32: 88 | D32: 0.29 | E32: 0.617 | F32: 0.483 | G32: preliminaries (13); proof of lemma (8); notation (7) | H32: defines_notation | I32: Defines specific mathematical or symbolic notation used in the paper, including explanations of symbols, mathematical concepts, and conventions. | L32: The authors define and use specific notation throughout the paper. | M32: The authors define mathematical notations and concepts used in the paper. | N32: The authors introduce notation and definitions used throughout the text. | O32: notation_definition (32), notation_simplification (13), notation_description (12), notation_introduction (9), notation_convention (9) | P32: c015 0.56, c017 0.55, c026 0.55 | Q32: keep | R32: defines_notation | W32: =IF(T32="accept",R32,U32)
A33: c031 | B33: 226 | C33: 5 | D33: 0.017 | E33: 0.3731 | F33: 0.545 | G33: literature review (33); introduction (9); timesat implementation (8) | H33: describes_method_and_data | I33: Describes the methods, data, and environmental factors used in the research, including the importance of specific measurements and their applications in agricultural management and monitoring. | L33: The authors highlight the use of remote sensing for monitoring crop phenology over large areas. | M33: The authors describe the different phases of crop growth and their relation to the NDVI time-series. | N33: The authors explain the classification and regression approaches to phenology estimation in the literature. | O33: method_description (10), finding_description (8), describing_data (5), metric_explanation (5), data_analysis (4) | P33: c053 0.40, c015 0.31, c026 0.30 | Q33: merge | R33: describes_method_details | W33: =IF(T33="accept",R33,U33)
A34: c032 | B34: 220 | C34: 44 | D34: 0.145 | E34: 0.4785 | F34: 0.472 | G34: notation (8); matrix algebra and eigendecomposition (8); step subspace estimation via a spectral method (6) | H34: matrix_and_tensor_operations | I34: Describes the use of matrix and tensor operations, including decompositions, eigenvectors, and other linear algebra techniques, often for dimensionality reduction or data analysis. | L34: SVD factorizes the normalized matrix into a diagonal matrix of singular values and two orthogonal matrices of singular vectors. | M34: The authors use the singular value decomposition (SVD) to analyze a matrix term in their derivation. | N34: The authors define a vector using the spectral decomposition of the Hessian matrix. | O34: method_description (16), notation_definition (9), matrix_definition (6), describe_data_or_method (5), dimensionality_reduction (3) | P34: c079 0.25, c028 0.24, c024 0.22 | Q34: merge | R34: describes_method_details | W34: =IF(T34="accept",R34,U34)
A35: c033 | B35: 202 | C35: 47 | D35: 0.155 | E35: 0.4769 | F35: 0.491 | G35: introduction (13); abstract (12); inverse probability weighting (7) | H35: estimator_properties | I35: States that the authors describe, prove, or verify properties of estimators, such as unbiasedness, variance reduction, and optimality. | L35: The authors report that the control variates estimator is unbiased and has the least variance among other unbiased estimators. | M35: The authors prove that the estimator is unbiased and has bounded variance for all agents. | N35: The authors introduce a proposition that the single-time-step doubly robust estimator of transitions in the marginal MDP is unbiased under certain conditions. | O35: method_description (8), variance_reduction (4), reporting_results (3), estimator_definition (3), describing_data_or_method (3) | P35: c006 0.40, c075 0.37, c021 0.33 | Q35: merge | R35: states_theoretical_result | W35: =IF(T35="accept",R35,U35)
A36: c034 | B36: 198 | C36: 88 | D36: 0.29 | E36: 0.4546 | F36: 0.526 | G36: synthetic datasets (12); introduction (9); abstract (6) | H36: data_generation_method | I36: Describes the method used by the authors to generate synthetic datasets, including the specific procedures, assumptions, and properties of the generated data. | L36: The authors use a specific procedure to generate synthetic data. | M36: The authors describe the method used to generate synthetic data. | N36: The authors describe the synthetic dataset generation process and its properties. | O36: method_description (34), data_description (18), data_generation (5), data_creation (5), type_explanation (4) | P36: c073 0.50, c059 0.42, c071 0.41 | Q36: keep | R36: generates_synthetic_data | W36: =IF(T36="accept",R36,U36)
A37: c035 | B37: 196 | C37: 82 | D37: 0.271 | E37: 0.5356 | F37: 0.51 | G37: data (10); change detection land cover map update (9); methodology (6) | H37: describes_preprocessing_steps | I37: Describes the specific preprocessing steps applied to data, including transformations, corrections, and other methods used to prepare the data for analysis or modeling. | L37: The authors describe the pre-processing steps applied to Sentinel-2A data, including downloading, transformation, and resampling. | M37: The authors pre-processed Sentinel-1 data using several steps including clipping, radiometric calibration, speckle filtering, terrain correction, and conversion of backscatter coefficient into decibels. | N37: The authors describe the method for processing ground-level data, including splitting into training and test data and storing in directories. | O37: data_preprocessing (37), method_description (15), preprocessing_steps (9), data_processing (8), preprocessing_description (6) | P37: c045 0.62, c073 0.40, c034 0.36 | Q37: merge | R37: describes_preprocessing | W37: =IF(T37="accept",R37,U37)
A38: c036 | B38: 193 | C38: 99 | D38: 0.327 | E38: 0.666 | F38: 0.605 | G38: results (15); conclusion (9); introduction (8) | H38: performance_comparison | I38: Reports that the authors' model or method outperforms other models or baselines on specific datasets or metrics. | J38: duplicate_name | L38: The authors report that RadNet outperforms benchmark models across all metrics for the RadSet dataset. | M38: The authors report that RadNet outperforms benchmark models for the METR-LA dataset, with an average F1 score of 0.651, which is 14.0% higher than the next best average F1 of the DKFN model. | N38: The authors report that ConfVAE outperforms existing state-of-the-art approaches on several benchmarks. | O38: performance_comparison (34), performance_report (13), specific_performance (8), performance_improvement (8), model_performance (7) | P38: c023 0.69, c077 0.66, c062 0.60 | Q38: merge | R38: reports_outperforming_others | W38: =IF(T38="accept",R38,U38)
A39: c037 | B39: 184 | C39: 83 | D39: 0.274 | E39: 0.5975 | F39: 0.449 | G39: some notations (6); loss function (5); writing relevance training (5) | H39: loss_function_description | I39: Describes the components, structure, and specific types of loss functions used in the model, including terms like cross-entropy, mean squared error, and regularization losses. | L39: The authors describe their loss function, which consists of two parts: a prediction loss and a graph structure preserving loss. | M39: The authors describe the loss function with terms for empirical risk, domain discrepancy, and reconstruction loss. | N39: The authors specify the components of the loss function, including cross-entropy loss and score ranking regularization loss. | O39: loss_function (27), method_description (18), loss_definition (10), loss_function_description (9), training_objective (5) | P39: c070 0.54, c019 0.40, c051 0.29 | Q39: merge | R39: describes_training_objective | W39: =IF(T39="accept",R39,U39)
A40: c038 | B40: 183 | C40: 109 | D40: 0.36 | E40: 0.658 | F40: 0.514 | G40: abstract (15); baselines (12); experiments (9) | H40: method_comparison | I40: Compares the authors' method with other existing methods, algorithms, or baselines to evaluate performance. | L40: The authors compare their method with several existing methods. | M40: The authors compare their method with state-of-the-art baselines. | N40: The authors compare their method against several baselines. | O40: method_comparison (40), performance_comparison (16), algorithm_comparison (8), baseline_comparison (8), comparison_method (7) | P40: c036 0.58, c047 0.54, c023 0.51 | Q40: merge | R40: reports_outperforming_others | W40: =IF(T40="accept",R40,U40)
A41: c039 | B41: 177 | C41: 48 | D41: 0.158 | E41: 0.4967 | F41: 0.443 | G41: introduction (15); abstract (11); conclusion (10) | H41: forecasting_method_description | I41: Describes the methods, models, and processes used by the authors for forecasting, including the specific techniques and data used for prediction. | L41: The authors describe the use of ML models for forecasting future trends according to previously collected data. | M41: The authors describe their approach for multiple-step forecasting using a linear regressor. | N41: The authors develop an online time series forecasting framework inspired by the Complementary Learning Systems theory. | O41: method_description (19), problem_description (3), data_usage (3), model_description (3), method_proposal (3) | P41: c056 0.36, c006 0.17, c033 0.17 | Q41: merge | R41: describes_method_details | W41: =IF(T41="accept",R41,U41)
A42: c040 | B42: 172 | C42: 104 | D42: 0.343 | E42: 0.5442 | F42: 0.368 | G42: related work (31); introduction (11); conclusion (7) | H42: compare_to_prior_work | I42: States that the authors' work differs from or contrasts with prior research, highlighting specific aspects or methods that set their approach apart. | L42: The authors state that their method differs from existing works in adopting a separate exploration policy. | M42: The authors describe how their work differs from previous work. | N42: The authors describe their method and how it differs from previous work. | O42: state_difference (7), compare_to_other_work (7), novelty_claim (7), method_comparison (5), first_of_its_kind (5) | P42: c020 0.63, c011 0.49, c050 0.42 | Q42: keep | R42: states_difference_from_prior_work | W42: =IF(T42="accept",R42,U42)
A43: c041 | B43: 168 | C43: 102 | D43: 0.337 | E43: 0.5069 | F43: 0.66 | G43: experimental setup (4); experiments (4); network design and optimization (4) | H43: hyperparameter_and_method_consistency | I43: States that the authors use the same or similar hyperparameters, methods, or configurations as those used in other works or sections of their own work for consistency and fair comparison. | L43: The authors train and evaluate the models using the same hyper-parameters as described in the original works. | M43: The authors use the same training hyperparameters as in the previous sections. | N43: The authors state that the hyperparameters used for training are the same as those used in a previously introduced model. | O43: fair_comparison (9), method_description (6), hyperparameter_consistency (3), method_consistency (3), unchanged_elements (3) | P43: c011 0.48, c075 0.42, c047 0.34 | Q43: merge | R43: specifies_hyperparameters | W43: =IF(T43="accept",R43,U43)
A44: c042 | B44: 167 | C44: 93 | D44: 0.307 | E44: 0.5223 | F44: 0.255 | G44: introduction (55); abstract (20); related work (12) | H44: reports_recent_advancements | I44: Reports that recent advancements in deep learning or machine learning have improved performance or achieved significant success in various tasks. | L44: The authors report recent advancements in deep learning approaches for time-series anomaly detection. | M44: The authors report that recent unsupervised deep learning-based approaches have improved performance in complex multivariate time-series anomaly detection tasks. | N44: The authors report that deep learning has revolutionized many machine learning tasks. | O44: method_description (6), method_proposal (5), key_advances (4), describing_data_or_method (4), progress_report (3) | P44: c020 0.46, c023 0.43, c077 0.40 | Q44: merge | R44: reviews_prior_work | W44: =IF(T44="accept",R44,U44)
A45: c043 | B45: 161 | C45: 42 | D45: 0.139 | E45: 0.5622 | F45: 0.463 | G45: abstract (9); the (6); convergence analysis for symmetric positive definite quadratic (4) | H45: convergence_analysis | I45: States that the authors prove, establish, or provide bounds for the convergence properties of algorithms under specific conditions. | L45: The authors prove a convergence property for the update iterate defined by the derived method under certain conditions. | M45: The authors establish convergence of the algorithms using a fundamental inequality. | N45: The authors prove a main result about the convergence rate of the AFAFed algorithm under certain assumptions. | O45: convergence_rate (12), convergence_proof (5), convergence_condition (5), report_what_authors_did_or_found (4), describe_data_or_method (3) | P45: c021 0.52, c004 0.36, c033 0.33 | Q45: merge | R45: states_theoretical_result | W45: =IF(T45="accept",R45,U45)
A46: c044 | B46: 155 | C46: 79 | D46: 0.261 | E46: 0.5858 | F46: 0.49 | G46: (no heading) (8); fsnet pseudo alorithm (5); algorithms (5) | H46: algorithm_description | I46: Describes the detailed steps, initialization, and operation of a specific algorithm or method. | L46: The authors describe the algorithm for discovering incremental skills, including the initialization and update steps. | M46: The authors describe a detailed algorithm for their method. | N46: The authors provide a pseudo code for their algorithm, USS-UCB, detailing its operation and input requirements. | O46: algorithm_description (24), method_description (24), algorithm_provision (6), algorithm_steps (4), algorithm_summary (4) | P46: c050 0.61, c022 0.53, c069 0.49 | Q46: keep | R46: describes_algorithm_steps | W46: =IF(T46="accept",R46,U46)
A47: c045 | B47: 153 | C47: 79 | D47: 0.261 | E47: 0.5544 | F47: 0.506 | G47: eeg preprocessing pipeline (6); smr requirement (6); data (4) | H47: data_filtering_and_cleaning | I47: Describes the methods and criteria used by the authors to filter, clean, and preprocess data, including the removal of irrelevant, noisy, or low-quality elements. | L47: The authors describe the filtering process applied to the Reuters News Archive to ensure only relevant articles are retained. | M47: The authors describe the filtering process they performed to reduce noise in the term collections. | N47: The authors clean the extracted data by removing certain elements and correcting abbreviations. | O47: data_filtering (12), method_description (12), data_cleaning (9), exclusion_criteria (5), data_preprocessing (5) | P47: c035 0.62, c059 0.37, c046 0.27 | Q47: merge | R47: describes_preprocessing | W47: =IF(T47="accept",R47,U47)
A48: c046 | B48: 150 | C48: 43 | D48: 0.142 | E48: 0.4962 | F48: 0.459 | G48: interface design choices (9); who is measuring (8); dataset collection (7) | H48: describe_annotation_process | I48: Describes the process, methods, and guidelines used by the authors or their team for annotating data, including the recruitment of annotators, instructions given, and quality control measures. | L48: The authors recruited expert annotators following institutional guidelines. | M48: The authors describe the process of having the annotators perform the annotation task. | N48: The authors instruct annotators to build the data following specific guidelines. | O48: method_description (6), describe_data_method (4), data_annotation (4), annotation_process (3), data_collection_method (3) | P48: c057 0.37, c055 0.32, c048 0.32 | Q48: keep | R48: describes_annotation_process | W48: =IF(T48="accept",R48,U48)
A49: c047 | B49: 150 | C49: 73 | D49: 0.241 | E49: 0.598 | F49: 0.571 | G49: baselines (18); experiments (8); baseline details (5) | H49: baseline_usage | I49: Describes the use of one or more baseline methods or models for comparison in the experiments. | L49: The authors use five baselines introduced by other researchers. | M49: The authors provide results of a baseline method for comparison. | N49: The authors use a specific model as a baseline in their experiments. | O49: baseline_description (23), baseline_model (8), baseline_method (6), method_description (5), baseline_establishment (3) | P49: c038 0.54, c064 0.34, c041 0.34 | Q49: keep | R49: uses_baselines | W49: =IF(T49="accept",R49,U49)
A50: c048 | B50: 149 | C50: 28 | D50: 0.092 | E50: 0.43 | F50: 0.496 | G50: introduction (16); abstract (9); evaluation (8) | H50: reports_study_findings | I50: Reports the results and observations from empirical studies, including participants' responses, trust, and perceptions, but not methodological details or specific error patterns. | L50: The authors report that respondents expressed a strong desire for interactive explanations. | M50: The authors report an investigation into participants' trust in model predictions and willingness to share predictions under different conditions. | N50: The authors report that adding SHAP explanations significantly enhanced participants' trust and willingness to share compared to the control condition. | O50: report_finding (6), specific_error_pattern (4), method_description (4), reporting_results (3), learning_effect (2) | P50: c072 0.41, c046 0.32, c066 0.22 | Q50: merge | R50: reports_observations | W50: =IF(T50="accept",R50,U50)
...

Sheet Types
A1: Type id | B1: Name | C1: Definition | D1: Positive example 1 | E1: Positive example 2 | F1: Near miss | G1: Severity weight | H1: Section hint | I1: Label source | J1: Seeds | K1: Source clusters (proposed) | L1: Claims (your decisions) | M1: Notes
A2: motivates_problem | B2: motivates_problem | C2: States why the problem matters (its importance, prevalence, real-world risks or costs), usually in the introduction, without yet describing the authors' method. | D2: The authors describe the risks associated with false and misleading information about a topic. | E2: The authors state that misinformation about a topic is prevalent and poses high risks. | F2: The authors state that the content of their work represents their own opinion and not necessarily that of their employers or sponsors. | G2: 1 | H2: under a heading like 'introduction', in the first half of the document | K2: c053 | L2: =SUMIF(Clusters!$W$2:$W$81,A2,Clusters!$B$2:$B$81) | M2: auto-filled, check: positive_examples, near_miss, section_hint
A3: reviews_prior_work | B3: reviews_prior_work | C3: Reviews or cites previous work on the problem or on background methods, including recent advances in the field, without contrasting it with the authors' own contribution. | D3: The authors review prior work on the problem and its limitations. | E3: The authors relate their work to previous attempts found in the literature. | F3: The authors direct the reader to the appendix for more details. | G3: 1 | H3: under a heading like 'related work', in the first half of the document | K3: c016, c011, c042 | L3: =SUMIF(Clusters!$W$2:$W$81,A3,Clusters!$B$2:$B$81) | M3: auto-filled, check: positive_examples, near_miss, section_hint
A4: states_difference_from_prior_work | B4: states_difference_from_prior_work | C4: States how the authors' work differs from, or is novel with respect to, specific prior work. | D4: The authors state that their method differs from existing works in adopting a separate exploration policy. | E4: The authors describe how their work differs from previous work. | F4: The authors propose a new method called SpliMe to leverage static embedding models for temporal knowledge graphs. | G4: 1 | H4: under a heading like 'related work', in the first half of the document | K4: c040 | L4: =SUMIF(Clusters!$W$2:$W$81,A4,Clusters!$B$2:$B$81) | M4: auto-filled, check: positive_examples, near_miss, section_hint
A5: defines_task_or_problem_setting | B5: defines_task_or_problem_setting | C5: Defines the task, problem or formal setting the paper addresses (inputs, outputs, objective; for example a sequence-labelling task or a Markov decision process). | D5: The authors describe the goal of the task as classifying a term as either literal or euphemistic. | E5: The authors define the action value function of a policy in terms of a trajectory generated by rolling out in the environment following the policy. | F5: The authors declare the mode of a predicate as an identity or inverse relationship with another predicate. | G5: 1 | H5: in the first half of the document | K5: c010, c008 | L5: =SUMIF(Clusters!$W$2:$W$81,A5,Clusters!$B$2:$B$81) | M5: c008 (MDP components, 64 papers) is topic-flavoured but is a problem formalisation; auto-filled, check: positive_examples, near_miss, section_hint
A6: proposes_method | B6: proposes_method | C6: Announces the authors' proposed method, model, algorithm or framework, often by name, as the paper's contribution. | D6: The authors propose a new method called SpliMe to leverage static embedding models for temporal knowledge graphs. | E6: The authors propose a novel algorithm named ${\tt LyOn}$ for solving constrained bandit optimization problems. | F6: The authors state that their method differs from existing works in adopting a separate exploration policy. | G6: 1 | H6: under a heading like 'abstract', in the first half of the document | J6: neurips_1 | K6: c020, c050 | L6: =SUMIF(Clusters!$W$2:$W$81,A6,Clusters!$B$2:$B$81) | M6: auto-filled, check: positive_examples, near_miss, section_hint
A7: states_method_advantages | B7: states_method_advantages | C7: States an advantage of the proposed method, such as needing less data, no retraining or fewer resources than alternatives. | D7: The authors state that CBLN can learn new tasks without forgetting previously learned ones. | E7: The authors state that their proposed method does not require access to model internals or retraining. | F7: The authors enable both zero-shot and multi-task transfer learning. | G7: 1 | H7: under a heading like 'abstract', in the first half of the document | K7: c049 | L7: =SUMIF(Clusters!$W$2:$W$81,A7,Clusters!$B$2:$B$81) | M7: auto-filled, check: positive_examples, near_miss, section_hint
A8: claims_broader_applicability | B8: claims_broader_applicability | C8: States that the method or framework can be applied or generalised to other domains, tasks or settings. | D8: The authors suggest that the framework has potential applications in other scenarios. | E8: The authors state that the methodology and algorithms can be applied in various domains. | F8: The authors suggest future work on the framework. | G8: 1 | H8: under a heading like 'introduction', in the first half of the document | K8: c058 | L8: =SUMIF(Clusters!$W$2:$W$81,A8,Clusters!$B$2:$B$81) | M8: auto-filled, check: positive_examples, near_miss, section_hint
A9: defines_notation | B9: defines_notation | C9: Defines the mathematical or symbolic notation used in the paper. | D9: The authors define and use specific notation throughout the paper. | E9: The authors define mathematical notations and concepts used in the paper. | F9: The authors direct the reader to the appendix for more details. | G9: 1 | H9: in the first half of the document | K9: c030 | L9: =SUMIF(Clusters!$W$2:$W$81,A9,Clusters!$B$2:$B$81) | M9: auto-filled, check: positive_examples, near_miss, section_hint
A10: states_modeling_assumptions | B10: states_modeling_assumptions | C10: States the assumptions the model or analysis rests on (distributions, independence, known quantities, conditions under which results hold). | D10: The authors assume a random variable follows a distribution from the exponential family with respect to a base measure. | E10: The authors assume a known distribution for a variable in the model. | F10: The authors report that the control variates estimator is unbiased and has the least variance among other unbiased estimators. | G10: 1 | H10: in the first half of the document | J10: neurips_3 | K10: c006 | L10: =SUMIF(Clusters!$W$2:$W$81,A10,Clusters!$B$2:$B$81) | M10: auto-filled, check: positive_examples, near_miss, section_hint
A11: states_theoretical_result | B11: states_theoretical_result | C11: States a theorem or formal guarantee (convergence, regret or error bounds, properties of an estimator) as a result of the paper. | D11: The authors present a theorem that describes a condition for the optimal transport plan. | E11: The authors prove a convergence property for the update iterate defined by the derived method under certain conditions. | F11: The authors provide a proof for Theorem [ref] that relies on an auxiliary result. | G11: 1 | H11: in the first half of the document | J11: neurips_3 | K11: c074, c043, c021, c033 | L11: =SUMIF(Clusters!$W$2:$W$81,A11,Clusters!$B$2:$B$81) | M11: auto-filled, check: positive_examples, near_miss, section_hint
A12: proves_or_derives | B12: proves_or_derives | C12: Carries out or reports steps of a proof or derivation (applying a lemma, deriving a bound or expression, establishing a property of a function). | D12: The authors provide a proof for Theorem [ref] that relies on an auxiliary result. | E12: The authors use mathematical inequalities and properties to derive bounds. | F12: The authors present a theorem that describes a condition for the optimal transport plan. | G12: 1 | H12: in the second half of the document | J12: neurips_3 | K12: c009, c060, c017, c079 | L12: =SUMIF(Clusters!$W$2:$W$81,A12,Clusters!$B$2:$B$81) | M12: the over-split proofs seen in the 3.1 eye test (residual c) land here; auto-filled, check: positive_examples, near_miss, section_hint
A13: describes_model_architecture | B13: describes_model_architecture | C13: Describes the structure of the model or system (layers, modules, components and how they connect). | D13: The authors describe the process of encoding sequences through a multi-head attention and feed-forward network. | E13: The authors describe their framework consisting of three components: parser, dialogue manager, and generator. | F13: The authors initialize their model with the architecture and weights of a pre-existing visual language model and then finetune it for a specific task. | G13: 1 | H13: in the first half of the document | K13: c001, c069 | L13: =SUMIF(Clusters!$W$2:$W$81,A13,Clusters!$B$2:$B$81) | M13: auto-filled, check: positive_examples, near_miss, section_hint
A14: describes_training_objective | B14: describes_training_objective | C14: Describes the loss function or training objective, including regularisation terms. | D14: The authors describe their loss function, which consists of two parts: a prediction loss and a graph structure preserving loss. | E14: The authors propose a regularization loss to explicitly model the non-local dependencies among constituents that belong to the same pattern. | F14: The authors describe the update process for the regressor and EMA via SGD. | G14: 1 | H14: in the first half of the document | K14: c037, c070 | L14: =SUMIF(Clusters!$W$2:$W$81,A14,Clusters!$B$2:$B$81) | M14: auto-filled, check: positive_examples, near_miss, section_hint
A15: describes_training_procedure | B15: describes_training_procedure | C15: Describes how the model is trained or optimised (training steps, update rules, optimisation algorithm, initialisation). | D15: The authors specify the training process for their models. | E15: The authors describe the update process for the regressor and EMA via SGD. | F15: The authors initialize their model with the architecture and weights of a pre-existing visual language model and then finetune it for a specific task. | G15: 1 | H15: in the first half of the document | J15: neurips_4 | K15: c051, c019, c027 | L15: =SUMIF(Clusters!$W$2:$W$81,A15,Clusters!$B$2:$B$81) | M15: auto-filled, check: positive_examples, near_miss, section_hint
A16: describes_algorithm_steps | B16: describes_algorithm_steps | C16: Describes an algorithm step by step (initialisation, iterations, termination), often with reference to pseudocode. | D16: The authors describe the algorithm for discovering incremental skills, including the initialization and update steps. | E16: The authors describe a detailed algorithm for their method. | F16: The authors propose a novel algorithm named ${\tt LyOn}$ for solving constrained bandit optimization problems. | G16: 1 | H16: in the first half of the document | K16: c044 | L16: =SUMIF(Clusters!$W$2:$W$81,A16,Clusters!$B$2:$B$81) | M16: auto-filled, check: positive_examples, near_miss, section_hint
A17: describes_method_details | B17: describes_method_details | C17: Describes how a specific technique or component of the approach works (for example a graph construction, a sampling scheme, a classifier, a decomposition), when no more specific method type applies. | D17: The authors develop a version of Q-learning for finite horizon Markov decision processes. | E17: The authors state that they will discuss adversarial attacks against black-box machine learning models and iML inspired contributions to combat them. | F17: The authors define the action value function of a policy in terms of a trajectory generated by rolling out in the environment following the policy. | G17: 1 | H17: in the first half of the document | K17: c012, c013, c024, c026, c028, c032, c039, c056, c059, c065, c066, c067, c068, c076, c078, c031 | L17: =SUMIF(Clusters!$W$2:$W$81,A17,Clusters!$B$2:$B$81) | M17: generic catch-all for topic-flavoured method clusters (RL, adversarial attacks, graphs, logic predicates, clustering, linear algebra, forecasting, classifiers, sampling, FL/CL, theories, transfer learning, summarisation, RDF, interpretability, remote sensing). c031 comes from 5 papers, c068 from 13, c076 from 19: prune them instead if you prefer. Near-universal, so it will rarely be 'absent'; it exists so that method sections map to something in 3.5; auto-filled, check: positive_examples, near_miss, section_hint
A18: fine_tunes_pretrained_model | B18: fine_tunes_pretrained_model | C18: States that a pre-trained model is fine-tuned on the task or data, with what model and data. | D18: The authors initialize their model with the architecture and weights of a pre-existing visual language model and then finetune it for a specific task. | E18: The authors fine-tune the model on the ID training data with specified hyperparameters. | F18: The authors describe the update process for the regressor and EMA via SGD. | G18: 1 | H18: in the first half of the document | K18: c063 | L18: =SUMIF(Clusters!$W$2:$W$81,A18,Clusters!$B$2:$B$81) | M18: auto-filled, check: positive_examples, near_miss, section_hint
A19: describes_data_augmentation | B19: describes_data_augmentation | C19: Describes how training data is augmented (transformations, synthetic variants, back-translation). | D19: The authors describe data augmentation as a method for creating variations of existing data. | E19: The authors describe the method they used for data augmentation, which involves back-translation. | F19: The authors use a specific procedure to generate synthetic data. | G19: 1 | H19: under a heading like 'data augmentation', in the first half of the document | K19: c073 | L19: =SUMIF(Clusters!$W$2:$W$81,A19,Clusters!$B$2:$B$81) | M19: auto-filled, check: positive_examples, near_miss, section_hint
A20: gives_illustrative_example | B20: gives_illustrative_example | C20: Gives a worked or illustrative example to explain a concept, method or result. | D20: The authors provide an example to illustrate the method. | E20: The authors present a concrete example to illustrate the concepts discussed. | F20: The authors visualize results using bar graphs. | G20: 1 | H20: in the first half of the document | K20: c061 | L20: =SUMIF(Clusters!$W$2:$W$81,A20,Clusters!$B$2:$B$81) | M20: auto-filled, check: positive_examples, near_miss, section_hint
A21: describes_datasets | B21: describes_datasets | C21: Describes the datasets used (source, content, domain, language), crediting where they come from. | D21: The authors describe the dataset they use for their experiments. | E21: The authors describe the datasets used in their experiments and their characteristics. | F21: The authors report the size of the datasets used in their experiments. | G21: 1 | H21: in the first half of the document | J21: neurips_12, acl_B1, acl_B5 | K21: c005 | L21: =SUMIF(Clusters!$W$2:$W$81,A21,Clusters!$B$2:$B$81) | M21: auto-filled, check: positive_examples, near_miss, section_hint
A22: introduces_dataset_or_benchmark | B22: introduces_dataset_or_benchmark | C22: Introduces a new dataset or benchmark created by the authors and describes its design and purpose. | D22: The authors introduce a new benchmark suite, S2-VLUE, to evaluate their proposed methods. | E22: The authors introduce benchmark datasets and baselines in this section. | F22: The authors conduct extensive experiments on real-world datasets to demonstrate the effectiveness of their methods. | G22: 1 | H22: under a heading like 'introduction', in the first half of the document | J22: neurips_13, acl_B5 | K22: c064 | L22: =SUMIF(Clusters!$W$2:$W$81,A22,Clusters!$B$2:$B$81) | M22: auto-filled, check: positive_examples, near_miss, section_hint
A23: reports_dataset_statistics | B23: reports_dataset_statistics | C23: Reports the size or other statistics of the datasets (number of examples, classes, tokens), often in a table. | D23: The authors report the size of the datasets used in their experiments. | E23: The authors report the statistics of datasets in a table. | F23: The authors describe the dataset they use for their experiments. | G23: 1 | H23: in the second half of the document | J23: acl_B6 | K23: c054 | L23: =SUMIF(Clusters!$W$2:$W$81,A23,Clusters!$B$2:$B$81) | M23: auto-filled, check: positive_examples, near_miss, section_hint
A24: describes_data_split | B24: describes_data_split | C24: States how the data is divided into training, validation and test sets (proportions, sizes, or the standard split used). | D24: The authors describe the division of the dataset into training, validation, and test sets. | E24: The authors divide the data set into training, validation, and testing sets with specified proportions. | F24: The authors describe the dataset they use for their experiments. | G24: 1 | H24: in the second half of the document | J24: neurips_6, acl_B6 | K24: c025 | L24: =SUMIF(Clusters!$W$2:$W$81,A24,Clusters!$B$2:$B$81) | M24: auto-filled, check: positive_examples, near_miss, section_hint
A25: describes_preprocessing | B25: describes_preprocessing | C25: Describes how data is preprocessed, filtered or cleaned before use (tokenisation, normalisation, removal of noisy or irrelevant items). | D25: The authors describe the pre-processing steps applied to Sentinel-2A data, including downloading, transformation, and resampling. | E25: The authors describe the filtering process applied to the Reuters News Archive to ensure only relevant articles are retained. | F25: The authors describe data augmentation as a method for creating variations of existing data. | G25: 1 | H25: in the second half of the document | K25: c035, c045 | L25: =SUMIF(Clusters!$W$2:$W$81,A25,Clusters!$B$2:$B$81) | M25: auto-filled, check: positive_examples, near_miss, section_hint
A26: generates_synthetic_data | B26: generates_synthetic_data | C26: Describes how synthetic or simulated data is generated for experiments. | D26: The authors use a specific procedure to generate synthetic data. | E26: The authors describe the method used to generate synthetic data. | F26: The authors describe data augmentation as a method for creating variations of existing data. | G26: 1 | H26: in the second half of the document | K26: c034 | L26: =SUMIF(Clusters!$W$2:$W$81,A26,Clusters!$B$2:$B$81) | M26: auto-filled, check: positive_examples, near_miss, section_hint
A27: describes_annotation_process | B27: describes_annotation_process | C27: Describes how data was annotated (guidelines, who annotated, how annotators were recruited or trained, agreement). | D27: The authors recruited expert annotators following institutional guidelines. | E27: The authors describe the process of having the annotators perform the annotation task. | F27: The authors state that the content of their work represents their own opinion and not necessarily that of their employers or sponsors. | G27: 1 | H27: in the first half of the document | J27: neurips_14, acl_D1, acl_D2, acl_D5 | K27: c046 | L27: =SUMIF(Clusters!$W$2:$W$81,A27,Clusters!$B$2:$B$81) | M27: auto-filled, check: positive_examples, near_miss, section_hint
A28: describes_evaluation_metrics | B28: describes_evaluation_metrics | C28: States which metrics or evaluation procedures are used to measure performance. | D28: The authors describe the evaluation method used in their experiments, referring to it as F1 score. | E28: The authors state that they compute accuracy, macro F1-score, and Cohen's kappa for performance evaluation. | F28: The authors introduce a new benchmark suite, S2-VLUE, to evaluate their proposed methods. | G28: 1 | H28: in the first half of the document | K28: c002 | L28: =SUMIF(Clusters!$W$2:$W$81,A28,Clusters!$B$2:$B$81) | M28: auto-filled, check: positive_examples, near_miss, section_hint
A29: specifies_hyperparameters | B29: specifies_hyperparameters | C29: Reports hyperparameter values or how they were chosen (learning rate, batch size, epochs, search procedure), including using the same settings as another work for a fair comparison. | D29: The authors specify the parameters used during the fine-tuning process, such as the number of epochs, dropout probability, batch size, and learning rates. | E29: The authors train and evaluate the models using the same hyper-parameters as described in the original works. | F29: The authors initialize their model with the architecture and weights of a pre-existing visual language model and then finetune it for a specific task. | G29: 1 | H29: in the second half of the document | J29: neurips_4, neurips_6, acl_C2 | K29: c003, c041 | L29: =SUMIF(Clusters!$W$2:$W$81,A29,Clusters!$B$2:$B$81) | M29: auto-filled, check: positive_examples, near_miss, section_hint
A30: uses_baselines | B30: uses_baselines | C30: Names or describes the baseline methods the approach is compared against. | D30: The authors use five baselines introduced by other researchers. | E30: The authors provide results of a baseline method for comparison. | F30: The authors compare their method with several existing methods. | G30: 1 | H30: under a heading like 'baselines', in the second half of the document | K30: c047 | L30: =SUMIF(Clusters!$W$2:$W$81,A30,Clusters!$B$2:$B$81) | M30: auto-filled, check: positive_examples, near_miss, section_hint
A31: specifies_compute_resources | B31: specifies_compute_resources | C31: States the hardware and computing environment used (GPUs, CPUs, memory, cluster), sometimes with run time. | D31: The authors describe the hardware and software environment used for the simulations. | E31: The authors describe the hardware and software environment used for the experiments. | F31: The authors use a specific software library for their implementation. | G31: 1 | H31: in the second half of the document | J31: neurips_8, acl_C1 | K31: c071 | L31: =SUMIF(Clusters!$W$2:$W$81,A31,Clusters!$B$2:$B$81) | M31: auto-filled, check: positive_examples, near_miss, section_hint
